[2023-01-15T10:52:42.683+0200] {taskinstance.py:1087} INFO - Dependencies all met for <TaskInstance: railway_v02.etl_pipeline scheduled__2022-12-16T00:00:00+00:00 [queued]>
[2023-01-15T10:52:42.709+0200] {taskinstance.py:1087} INFO - Dependencies all met for <TaskInstance: railway_v02.etl_pipeline scheduled__2022-12-16T00:00:00+00:00 [queued]>
[2023-01-15T10:52:42.714+0200] {taskinstance.py:1283} INFO - 
--------------------------------------------------------------------------------
[2023-01-15T10:52:42.715+0200] {taskinstance.py:1284} INFO - Starting attempt 4 of 6
[2023-01-15T10:52:42.716+0200] {taskinstance.py:1285} INFO - 
--------------------------------------------------------------------------------
[2023-01-15T10:52:42.737+0200] {taskinstance.py:1304} INFO - Executing <Task(_PythonDecoratedOperator): etl_pipeline> on 2022-12-16 00:00:00+00:00
[2023-01-15T10:52:42.764+0200] {standard_task_runner.py:55} INFO - Started process 30731 to run task
[2023-01-15T10:52:42.791+0200] {standard_task_runner.py:82} INFO - Running: ['airflow', 'tasks', 'run', 'railway_v02', 'etl_pipeline', 'scheduled__2022-12-16T00:00:00+00:00', '--job-id', '403', '--raw', '--subdir', 'DAGS_FOLDER/fetching_api.py', '--cfg-path', '/var/folders/qr/k2__dmk5697g2jyd7w2tpyt80000gn/T/tmpgriw5mhz']
[2023-01-15T10:52:42.795+0200] {standard_task_runner.py:83} INFO - Job 403: Subtask etl_pipeline
[2023-01-15T10:52:42.971+0200] {task_command.py:389} INFO - Running <TaskInstance: railway_v02.etl_pipeline scheduled__2022-12-16T00:00:00+00:00 [running]> on host nhanchaus-macbook-air.local
[2023-01-15T10:52:43.135+0200] {taskinstance.py:1511} INFO - Exporting the following env vars:
AIRFLOW_CTX_DAG_OWNER=Nhan_Chau
AIRFLOW_CTX_DAG_ID=railway_v02
AIRFLOW_CTX_TASK_ID=etl_pipeline
AIRFLOW_CTX_EXECUTION_DATE=2022-12-16T00:00:00+00:00
AIRFLOW_CTX_TRY_NUMBER=4
AIRFLOW_CTX_DAG_RUN_ID=scheduled__2022-12-16T00:00:00+00:00
[2023-01-15T10:55:35.973+0200] {logging_mixin.py:137} WARNING - ----------------------------------------
[2023-01-15T10:55:35.975+0200] {clientserver.py:538} INFO - Error while receiving.
Traceback (most recent call last):
  File "/Library/Frameworks/Python.framework/Versions/3.10/lib/python3.10/site-packages/py4j/clientserver.py", line 516, in send_command
    raise Py4JNetworkError("Answer from Java side is empty")
py4j.protocol.Py4JNetworkError: Answer from Java side is empty
[2023-01-15T10:55:35.979+0200] {logging_mixin.py:137} WARNING - Exception occurred during processing of request from ('127.0.0.1', 63950)
[2023-01-15T10:55:35.985+0200] {clientserver.py:543} INFO - Closing down clientserver connection
[2023-01-15T10:55:35.986+0200] {java_gateway.py:1055} ERROR - Exception while sending command.
Traceback (most recent call last):
  File "/Library/Frameworks/Python.framework/Versions/3.10/lib/python3.10/site-packages/py4j/clientserver.py", line 516, in send_command
    raise Py4JNetworkError("Answer from Java side is empty")
py4j.protocol.Py4JNetworkError: Answer from Java side is empty

During handling of the above exception, another exception occurred:

Traceback (most recent call last):
  File "/Library/Frameworks/Python.framework/Versions/3.10/lib/python3.10/site-packages/py4j/java_gateway.py", line 1038, in send_command
    response = connection.send_command(command)
  File "/Library/Frameworks/Python.framework/Versions/3.10/lib/python3.10/site-packages/py4j/clientserver.py", line 539, in send_command
    raise Py4JNetworkError(
py4j.protocol.Py4JNetworkError: Error while sending or receiving
[2023-01-15T10:55:35.987+0200] {logging_mixin.py:137} WARNING - Traceback (most recent call last):
[2023-01-15T10:55:35.988+0200] {clientserver.py:543} INFO - Closing down clientserver connection
[2023-01-15T10:55:35.988+0200] {logging_mixin.py:137} WARNING -   File "/Library/Frameworks/Python.framework/Versions/3.10/lib/python3.10/socketserver.py", line 316, in _handle_request_noblock
    self.process_request(request, client_address)
[2023-01-15T10:55:35.989+0200] {taskinstance.py:1772} ERROR - Task failed with exception
Traceback (most recent call last):
  File "/Library/Frameworks/Python.framework/Versions/3.10/lib/python3.10/site-packages/airflow/decorators/base.py", line 217, in execute
    return_value = super().execute(context)
  File "/Library/Frameworks/Python.framework/Versions/3.10/lib/python3.10/site-packages/airflow/operators/python.py", line 175, in execute
    return_value = self.execute_callable()
  File "/Library/Frameworks/Python.framework/Versions/3.10/lib/python3.10/site-packages/airflow/operators/python.py", line 192, in execute_callable
    return self.python_callable(*self.op_args, **self.op_kwargs)
  File "/Users/nhanchau/gitRepo/Raiway_with_AIrflow/dags/fetching_api.py", line 108, in etl_pipeline
    (v
  File "/Library/Frameworks/Python.framework/Versions/3.10/lib/python3.10/site-packages/pyspark/sql/readwriter.py", line 1340, in jdbc
    self.mode(mode)._jwrite.jdbc(url, table, jprop)
  File "/Library/Frameworks/Python.framework/Versions/3.10/lib/python3.10/site-packages/py4j/java_gateway.py", line 1321, in __call__
    return_value = get_return_value(
  File "/Library/Frameworks/Python.framework/Versions/3.10/lib/python3.10/site-packages/pyspark/sql/utils.py", line 190, in deco
    return f(*a, **kw)
  File "/Library/Frameworks/Python.framework/Versions/3.10/lib/python3.10/site-packages/py4j/protocol.py", line 334, in get_return_value
    raise Py4JError(
py4j.protocol.Py4JError: An error occurred while calling o219.jdbc
[2023-01-15T10:55:35.989+0200] {logging_mixin.py:137} WARNING -   File "/Library/Frameworks/Python.framework/Versions/3.10/lib/python3.10/socketserver.py", line 347, in process_request
    self.finish_request(request, client_address)
[2023-01-15T10:55:36.001+0200] {logging_mixin.py:137} WARNING -   File "/Library/Frameworks/Python.framework/Versions/3.10/lib/python3.10/socketserver.py", line 360, in finish_request
    self.RequestHandlerClass(request, client_address, self)
[2023-01-15T10:55:36.001+0200] {logging_mixin.py:137} WARNING -   File "/Library/Frameworks/Python.framework/Versions/3.10/lib/python3.10/socketserver.py", line 747, in __init__
    self.handle()
[2023-01-15T10:55:36.002+0200] {logging_mixin.py:137} WARNING -   File "/Library/Frameworks/Python.framework/Versions/3.10/lib/python3.10/site-packages/pyspark/accumulators.py", line 281, in handle
    poll(accum_updates)
[2023-01-15T10:55:36.002+0200] {logging_mixin.py:137} WARNING -   File "/Library/Frameworks/Python.framework/Versions/3.10/lib/python3.10/site-packages/pyspark/accumulators.py", line 253, in poll
    if func():
[2023-01-15T10:55:36.003+0200] {logging_mixin.py:137} WARNING -   File "/Library/Frameworks/Python.framework/Versions/3.10/lib/python3.10/site-packages/pyspark/accumulators.py", line 257, in accum_updates
    num_updates = read_int(self.rfile)
[2023-01-15T10:55:36.003+0200] {logging_mixin.py:137} WARNING -   File "/Library/Frameworks/Python.framework/Versions/3.10/lib/python3.10/site-packages/pyspark/serializers.py", line 595, in read_int
    raise EOFError
[2023-01-15T10:55:36.004+0200] {logging_mixin.py:137} WARNING - EOFError
[2023-01-15T10:55:36.004+0200] {logging_mixin.py:137} WARNING - ----------------------------------------
[2023-01-15T10:55:36.016+0200] {taskinstance.py:1322} INFO - Marking task as UP_FOR_RETRY. dag_id=railway_v02, task_id=etl_pipeline, execution_date=20221216T000000, start_date=20230115T085242, end_date=20230115T085536
[2023-01-15T10:55:36.034+0200] {standard_task_runner.py:100} ERROR - Failed to execute job 403 for task etl_pipeline (An error occurred while calling o219.jdbc; 30731)
