[2023-01-15T07:41:07.591+0200] {taskinstance.py:1087} INFO - Dependencies all met for <TaskInstance: railway_v01.etl manual__2023-01-15T05:22:13.345799+00:00 [queued]>
[2023-01-15T07:41:07.600+0200] {taskinstance.py:1087} INFO - Dependencies all met for <TaskInstance: railway_v01.etl manual__2023-01-15T05:22:13.345799+00:00 [queued]>
[2023-01-15T07:41:07.601+0200] {taskinstance.py:1283} INFO - 
--------------------------------------------------------------------------------
[2023-01-15T07:41:07.601+0200] {taskinstance.py:1284} INFO - Starting attempt 7 of 12
[2023-01-15T07:41:07.601+0200] {taskinstance.py:1285} INFO - 
--------------------------------------------------------------------------------
[2023-01-15T07:41:07.609+0200] {taskinstance.py:1304} INFO - Executing <Task(_PythonDecoratedOperator): etl> on 2023-01-15 05:22:13.345799+00:00
[2023-01-15T07:41:07.615+0200] {standard_task_runner.py:55} INFO - Started process 11722 to run task
[2023-01-15T07:41:07.620+0200] {standard_task_runner.py:82} INFO - Running: ['airflow', 'tasks', 'run', 'railway_v01', 'etl', 'manual__2023-01-15T05:22:13.345799+00:00', '--job-id', '206', '--raw', '--subdir', 'DAGS_FOLDER/fetching_api.py', '--cfg-path', '/var/folders/qr/k2__dmk5697g2jyd7w2tpyt80000gn/T/tmpi_1g5sav']
[2023-01-15T07:41:07.624+0200] {standard_task_runner.py:83} INFO - Job 206: Subtask etl
[2023-01-15T07:41:07.692+0200] {task_command.py:389} INFO - Running <TaskInstance: railway_v01.etl manual__2023-01-15T05:22:13.345799+00:00 [running]> on host nhanchaus-macbook-air.local
[2023-01-15T07:41:07.755+0200] {taskinstance.py:1511} INFO - Exporting the following env vars:
AIRFLOW_CTX_DAG_OWNER=Nhan_Chau
AIRFLOW_CTX_DAG_ID=railway_v01
AIRFLOW_CTX_TASK_ID=etl
AIRFLOW_CTX_EXECUTION_DATE=2023-01-15T05:22:13.345799+00:00
AIRFLOW_CTX_TRY_NUMBER=7
AIRFLOW_CTX_DAG_RUN_ID=manual__2023-01-15T05:22:13.345799+00:00
[2023-01-15T07:41:27.437+0200] {taskinstance.py:1772} ERROR - Task failed with exception
Traceback (most recent call last):
  File "/Library/Frameworks/Python.framework/Versions/3.10/lib/python3.10/site-packages/airflow/decorators/base.py", line 217, in execute
    return_value = super().execute(context)
  File "/Library/Frameworks/Python.framework/Versions/3.10/lib/python3.10/site-packages/airflow/operators/python.py", line 175, in execute
    return_value = self.execute_callable()
  File "/Library/Frameworks/Python.framework/Versions/3.10/lib/python3.10/site-packages/airflow/operators/python.py", line 192, in execute_callable
    return self.python_callable(*self.op_args, **self.op_kwargs)
  File "/Users/nhanchau/gitRepo/Raiway_with_AIrflow/dags/fetching_api.py", line 124, in etl
    .save("s3a://arirflow-bucket/df"))
  File "/Library/Frameworks/Python.framework/Versions/3.10/lib/python3.10/site-packages/pyspark/sql/readwriter.py", line 968, in save
    self._jwrite.save(path)
  File "/Library/Frameworks/Python.framework/Versions/3.10/lib/python3.10/site-packages/py4j/java_gateway.py", line 1321, in __call__
    return_value = get_return_value(
  File "/Library/Frameworks/Python.framework/Versions/3.10/lib/python3.10/site-packages/pyspark/sql/utils.py", line 190, in deco
    return f(*a, **kw)
  File "/Library/Frameworks/Python.framework/Versions/3.10/lib/python3.10/site-packages/py4j/protocol.py", line 326, in get_return_value
    raise Py4JJavaError(
py4j.protocol.Py4JJavaError: An error occurred while calling o175.save.
: java.lang.RuntimeException: java.lang.ClassNotFoundException: Class org.apache.hadoop.fs.s3a.S3AFileSystem not found
	at org.apache.hadoop.conf.Configuration.getClass(Configuration.java:2688)
	at org.apache.hadoop.fs.FileSystem.getFileSystemClass(FileSystem.java:3431)
	at org.apache.hadoop.fs.FileSystem.createFileSystem(FileSystem.java:3466)
	at org.apache.hadoop.fs.FileSystem.access$300(FileSystem.java:174)
	at org.apache.hadoop.fs.FileSystem$Cache.getInternal(FileSystem.java:3574)
	at org.apache.hadoop.fs.FileSystem$Cache.get(FileSystem.java:3521)
	at org.apache.hadoop.fs.FileSystem.get(FileSystem.java:540)
	at org.apache.hadoop.fs.Path.getFileSystem(Path.java:365)
	at org.apache.spark.sql.execution.datasources.DataSource.planForWritingFileFormat(DataSource.scala:461)
	at org.apache.spark.sql.execution.datasources.DataSource.planForWriting(DataSource.scala:558)
	at org.apache.spark.sql.DataFrameWriter.saveToV1Source(DataFrameWriter.scala:390)
	at org.apache.spark.sql.DataFrameWriter.saveInternal(DataFrameWriter.scala:363)
	at org.apache.spark.sql.DataFrameWriter.save(DataFrameWriter.scala:239)
	at java.base/jdk.internal.reflect.DirectMethodHandleAccessor.invoke(DirectMethodHandleAccessor.java:104)
	at java.base/java.lang.reflect.Method.invoke(Method.java:578)
	at py4j.reflection.MethodInvoker.invoke(MethodInvoker.java:244)
	at py4j.reflection.ReflectionEngine.invoke(ReflectionEngine.java:357)
	at py4j.Gateway.invoke(Gateway.java:282)
	at py4j.commands.AbstractCommand.invokeMethod(AbstractCommand.java:132)
	at py4j.commands.CallCommand.execute(CallCommand.java:79)
	at py4j.ClientServerConnection.waitForCommands(ClientServerConnection.java:182)
	at py4j.ClientServerConnection.run(ClientServerConnection.java:106)
	at java.base/java.lang.Thread.run(Thread.java:1589)
Caused by: java.lang.ClassNotFoundException: Class org.apache.hadoop.fs.s3a.S3AFileSystem not found
	at org.apache.hadoop.conf.Configuration.getClassByName(Configuration.java:2592)
	at org.apache.hadoop.conf.Configuration.getClass(Configuration.java:2686)
	... 22 more

[2023-01-15T07:41:27.474+0200] {taskinstance.py:1322} INFO - Marking task as UP_FOR_RETRY. dag_id=railway_v01, task_id=etl, execution_date=20230115T052213, start_date=20230115T054107, end_date=20230115T054127
[2023-01-15T07:41:27.492+0200] {standard_task_runner.py:100} ERROR - Failed to execute job 206 for task etl (An error occurred while calling o175.save.
: java.lang.RuntimeException: java.lang.ClassNotFoundException: Class org.apache.hadoop.fs.s3a.S3AFileSystem not found
	at org.apache.hadoop.conf.Configuration.getClass(Configuration.java:2688)
	at org.apache.hadoop.fs.FileSystem.getFileSystemClass(FileSystem.java:3431)
	at org.apache.hadoop.fs.FileSystem.createFileSystem(FileSystem.java:3466)
	at org.apache.hadoop.fs.FileSystem.access$300(FileSystem.java:174)
	at org.apache.hadoop.fs.FileSystem$Cache.getInternal(FileSystem.java:3574)
	at org.apache.hadoop.fs.FileSystem$Cache.get(FileSystem.java:3521)
	at org.apache.hadoop.fs.FileSystem.get(FileSystem.java:540)
	at org.apache.hadoop.fs.Path.getFileSystem(Path.java:365)
	at org.apache.spark.sql.execution.datasources.DataSource.planForWritingFileFormat(DataSource.scala:461)
	at org.apache.spark.sql.execution.datasources.DataSource.planForWriting(DataSource.scala:558)
	at org.apache.spark.sql.DataFrameWriter.saveToV1Source(DataFrameWriter.scala:390)
	at org.apache.spark.sql.DataFrameWriter.saveInternal(DataFrameWriter.scala:363)
	at org.apache.spark.sql.DataFrameWriter.save(DataFrameWriter.scala:239)
	at java.base/jdk.internal.reflect.DirectMethodHandleAccessor.invoke(DirectMethodHandleAccessor.java:104)
	at java.base/java.lang.reflect.Method.invoke(Method.java:578)
	at py4j.reflection.MethodInvoker.invoke(MethodInvoker.java:244)
	at py4j.reflection.ReflectionEngine.invoke(ReflectionEngine.java:357)
	at py4j.Gateway.invoke(Gateway.java:282)
	at py4j.commands.AbstractCommand.invokeMethod(AbstractCommand.java:132)
	at py4j.commands.CallCommand.execute(CallCommand.java:79)
	at py4j.ClientServerConnection.waitForCommands(ClientServerConnection.java:182)
	at py4j.ClientServerConnection.run(ClientServerConnection.java:106)
	at java.base/java.lang.Thread.run(Thread.java:1589)
Caused by: java.lang.ClassNotFoundException: Class org.apache.hadoop.fs.s3a.S3AFileSystem not found
	at org.apache.hadoop.conf.Configuration.getClassByName(Configuration.java:2592)
	at org.apache.hadoop.conf.Configuration.getClass(Configuration.java:2686)
	... 22 more
; 11722)
[2023-01-15T07:41:27.532+0200] {local_task_job.py:159} INFO - Task exited with return code 1
[2023-01-15T07:41:27.563+0200] {taskinstance.py:2582} INFO - 0 downstream tasks scheduled from follow-on schedule check
