[2023-01-15T10:11:20.267+0200] {taskinstance.py:1087} INFO - Dependencies all met for <TaskInstance: railway_v02.etl_pipeline scheduled__2022-12-28T00:00:00+00:00 [queued]>
[2023-01-15T10:11:20.468+0200] {taskinstance.py:1087} INFO - Dependencies all met for <TaskInstance: railway_v02.etl_pipeline scheduled__2022-12-28T00:00:00+00:00 [queued]>
[2023-01-15T10:11:20.490+0200] {taskinstance.py:1283} INFO - 
--------------------------------------------------------------------------------
[2023-01-15T10:11:20.521+0200] {taskinstance.py:1284} INFO - Starting attempt 3 of 6
[2023-01-15T10:11:20.532+0200] {taskinstance.py:1285} INFO - 
--------------------------------------------------------------------------------
[2023-01-15T10:11:20.653+0200] {taskinstance.py:1304} INFO - Executing <Task(_PythonDecoratedOperator): etl_pipeline> on 2022-12-28 00:00:00+00:00
[2023-01-15T10:11:20.720+0200] {standard_task_runner.py:55} INFO - Started process 13663 to run task
[2023-01-15T10:11:20.795+0200] {standard_task_runner.py:82} INFO - Running: ['airflow', 'tasks', 'run', 'railway_v02', 'etl_pipeline', 'scheduled__2022-12-28T00:00:00+00:00', '--job-id', '320', '--raw', '--subdir', 'DAGS_FOLDER/fetching_api.py', '--cfg-path', '/var/folders/qr/k2__dmk5697g2jyd7w2tpyt80000gn/T/tmpf__0ejy5']
[2023-01-15T10:11:20.889+0200] {standard_task_runner.py:83} INFO - Job 320: Subtask etl_pipeline
[2023-01-15T10:11:22.994+0200] {task_command.py:389} INFO - Running <TaskInstance: railway_v02.etl_pipeline scheduled__2022-12-28T00:00:00+00:00 [running]> on host nhanchaus-macbook-air.local
[2023-01-15T10:11:24.386+0200] {taskinstance.py:1511} INFO - Exporting the following env vars:
AIRFLOW_CTX_DAG_OWNER=Nhan_Chau
AIRFLOW_CTX_DAG_ID=railway_v02
AIRFLOW_CTX_TASK_ID=etl_pipeline
AIRFLOW_CTX_EXECUTION_DATE=2022-12-28T00:00:00+00:00
AIRFLOW_CTX_TRY_NUMBER=3
AIRFLOW_CTX_DAG_RUN_ID=scheduled__2022-12-28T00:00:00+00:00
[2023-01-15T10:17:24.150+0200] {clientserver.py:538} INFO - Error while receiving.
Traceback (most recent call last):
  File "/Library/Frameworks/Python.framework/Versions/3.10/lib/python3.10/site-packages/py4j/clientserver.py", line 516, in send_command
    raise Py4JNetworkError("Answer from Java side is empty")
py4j.protocol.Py4JNetworkError: Answer from Java side is empty
[2023-01-15T10:17:24.196+0200] {clientserver.py:543} INFO - Closing down clientserver connection
[2023-01-15T10:17:24.199+0200] {java_gateway.py:1055} ERROR - Exception while sending command.
Traceback (most recent call last):
  File "/Library/Frameworks/Python.framework/Versions/3.10/lib/python3.10/site-packages/py4j/clientserver.py", line 516, in send_command
    raise Py4JNetworkError("Answer from Java side is empty")
py4j.protocol.Py4JNetworkError: Answer from Java side is empty

During handling of the above exception, another exception occurred:

Traceback (most recent call last):
  File "/Library/Frameworks/Python.framework/Versions/3.10/lib/python3.10/site-packages/py4j/java_gateway.py", line 1038, in send_command
    response = connection.send_command(command)
  File "/Library/Frameworks/Python.framework/Versions/3.10/lib/python3.10/site-packages/py4j/clientserver.py", line 539, in send_command
    raise Py4JNetworkError(
py4j.protocol.Py4JNetworkError: Error while sending or receiving
[2023-01-15T10:17:24.205+0200] {clientserver.py:543} INFO - Closing down clientserver connection
[2023-01-15T10:17:24.215+0200] {taskinstance.py:1772} ERROR - Task failed with exception
Traceback (most recent call last):
  File "/Library/Frameworks/Python.framework/Versions/3.10/lib/python3.10/site-packages/airflow/decorators/base.py", line 217, in execute
    return_value = super().execute(context)
  File "/Library/Frameworks/Python.framework/Versions/3.10/lib/python3.10/site-packages/airflow/operators/python.py", line 175, in execute
    return_value = self.execute_callable()
  File "/Library/Frameworks/Python.framework/Versions/3.10/lib/python3.10/site-packages/airflow/operators/python.py", line 192, in execute_callable
    return self.python_callable(*self.op_args, **self.op_kwargs)
  File "/Users/nhanchau/gitRepo/Raiway_with_AIrflow/dags/fetching_api.py", line 43, in etl_pipeline
    df_dict = {k: spark.createDataFrame(json.loads(v)) for (k,v) in res_dict.items()}
  File "/Users/nhanchau/gitRepo/Raiway_with_AIrflow/dags/fetching_api.py", line 43, in <dictcomp>
    df_dict = {k: spark.createDataFrame(json.loads(v)) for (k,v) in res_dict.items()}
  File "/Library/Frameworks/Python.framework/Versions/3.10/lib/python3.10/site-packages/pyspark/sql/session.py", line 894, in createDataFrame
    return self._create_dataframe(
  File "/Library/Frameworks/Python.framework/Versions/3.10/lib/python3.10/site-packages/pyspark/sql/session.py", line 939, in _create_dataframe
    jdf = self._jsparkSession.applySchemaToPythonRDD(jrdd.rdd(), struct.json())
  File "/Library/Frameworks/Python.framework/Versions/3.10/lib/python3.10/site-packages/py4j/java_gateway.py", line 1321, in __call__
    return_value = get_return_value(
  File "/Library/Frameworks/Python.framework/Versions/3.10/lib/python3.10/site-packages/pyspark/sql/utils.py", line 190, in deco
    return f(*a, **kw)
  File "/Library/Frameworks/Python.framework/Versions/3.10/lib/python3.10/site-packages/py4j/protocol.py", line 334, in get_return_value
    raise Py4JError(
py4j.protocol.Py4JError: An error occurred while calling o28.applySchemaToPythonRDD
[2023-01-15T10:17:24.421+0200] {taskinstance.py:1322} INFO - Marking task as UP_FOR_RETRY. dag_id=railway_v02, task_id=etl_pipeline, execution_date=20221228T000000, start_date=20230115T081120, end_date=20230115T081724
[2023-01-15T10:17:24.497+0200] {clientserver.py:538} INFO - Error while receiving.
Traceback (most recent call last):
  File "/Library/Frameworks/Python.framework/Versions/3.10/lib/python3.10/site-packages/py4j/clientserver.py", line 516, in send_command
    raise Py4JNetworkError("Answer from Java side is empty")
py4j.protocol.Py4JNetworkError: Answer from Java side is empty
[2023-01-15T10:17:24.506+0200] {clientserver.py:543} INFO - Closing down clientserver connection
[2023-01-15T10:17:24.507+0200] {java_gateway.py:1055} ERROR - Exception while sending command.
Traceback (most recent call last):
  File "/Library/Frameworks/Python.framework/Versions/3.10/lib/python3.10/site-packages/py4j/clientserver.py", line 516, in send_command
    raise Py4JNetworkError("Answer from Java side is empty")
py4j.protocol.Py4JNetworkError: Answer from Java side is empty

During handling of the above exception, another exception occurred:

Traceback (most recent call last):
  File "/Library/Frameworks/Python.framework/Versions/3.10/lib/python3.10/site-packages/py4j/java_gateway.py", line 1038, in send_command
    response = connection.send_command(command)
  File "/Library/Frameworks/Python.framework/Versions/3.10/lib/python3.10/site-packages/py4j/clientserver.py", line 539, in send_command
    raise Py4JNetworkError(
py4j.protocol.Py4JNetworkError: Error while sending or receiving
[2023-01-15T10:17:24.516+0200] {clientserver.py:543} INFO - Closing down clientserver connection
[2023-01-15T10:17:24.522+0200] {clientserver.py:543} INFO - Closing down clientserver connection
[2023-01-15T10:17:24.524+0200] {clientserver.py:543} INFO - Closing down clientserver connection
[2023-01-15T10:17:24.530+0200] {clientserver.py:543} INFO - Closing down clientserver connection
[2023-01-15T10:17:24.531+0200] {clientserver.py:543} INFO - Closing down clientserver connection
[2023-01-15T10:17:24.537+0200] {clientserver.py:543} INFO - Closing down clientserver connection
[2023-01-15T10:17:24.541+0200] {clientserver.py:543} INFO - Closing down clientserver connection
[2023-01-15T10:17:24.549+0200] {clientserver.py:543} INFO - Closing down clientserver connection
[2023-01-15T10:17:24.557+0200] {clientserver.py:543} INFO - Closing down clientserver connection
[2023-01-15T10:17:24.560+0200] {standard_task_runner.py:100} ERROR - Failed to execute job 320 for task etl_pipeline (An error occurred while calling o28.applySchemaToPythonRDD; 13663)
