[2023-01-15T10:41:17.552+0200] {taskinstance.py:1087} INFO - Dependencies all met for <TaskInstance: railway_v02.etl_pipeline scheduled__2022-12-23T00:00:00+00:00 [queued]>
[2023-01-15T10:41:17.608+0200] {taskinstance.py:1087} INFO - Dependencies all met for <TaskInstance: railway_v02.etl_pipeline scheduled__2022-12-23T00:00:00+00:00 [queued]>
[2023-01-15T10:41:17.614+0200] {taskinstance.py:1283} INFO - 
--------------------------------------------------------------------------------
[2023-01-15T10:41:17.615+0200] {taskinstance.py:1284} INFO - Starting attempt 4 of 6
[2023-01-15T10:41:17.615+0200] {taskinstance.py:1285} INFO - 
--------------------------------------------------------------------------------
[2023-01-15T10:41:17.710+0200] {taskinstance.py:1304} INFO - Executing <Task(_PythonDecoratedOperator): etl_pipeline> on 2022-12-23 00:00:00+00:00
[2023-01-15T10:41:17.746+0200] {standard_task_runner.py:55} INFO - Started process 26241 to run task
[2023-01-15T10:41:17.777+0200] {standard_task_runner.py:82} INFO - Running: ['airflow', 'tasks', 'run', 'railway_v02', 'etl_pipeline', 'scheduled__2022-12-23T00:00:00+00:00', '--job-id', '390', '--raw', '--subdir', 'DAGS_FOLDER/fetching_api.py', '--cfg-path', '/var/folders/qr/k2__dmk5697g2jyd7w2tpyt80000gn/T/tmpkle8hwh1']
[2023-01-15T10:41:17.785+0200] {standard_task_runner.py:83} INFO - Job 390: Subtask etl_pipeline
[2023-01-15T10:41:18.285+0200] {task_command.py:389} INFO - Running <TaskInstance: railway_v02.etl_pipeline scheduled__2022-12-23T00:00:00+00:00 [running]> on host nhanchaus-macbook-air.local
[2023-01-15T10:41:18.678+0200] {taskinstance.py:1511} INFO - Exporting the following env vars:
AIRFLOW_CTX_DAG_OWNER=Nhan_Chau
AIRFLOW_CTX_DAG_ID=railway_v02
AIRFLOW_CTX_TASK_ID=etl_pipeline
AIRFLOW_CTX_EXECUTION_DATE=2022-12-23T00:00:00+00:00
AIRFLOW_CTX_TRY_NUMBER=4
AIRFLOW_CTX_DAG_RUN_ID=scheduled__2022-12-23T00:00:00+00:00
[2023-01-15T10:45:10.231+0200] {clientserver.py:538} INFO - Error while receiving.
Traceback (most recent call last):
  File "/Library/Frameworks/Python.framework/Versions/3.10/lib/python3.10/site-packages/py4j/clientserver.py", line 516, in send_command
    raise Py4JNetworkError("Answer from Java side is empty")
py4j.protocol.Py4JNetworkError: Answer from Java side is empty
[2023-01-15T10:45:10.266+0200] {clientserver.py:543} INFO - Closing down clientserver connection
[2023-01-15T10:45:10.269+0200] {java_gateway.py:1055} ERROR - Exception while sending command.
Traceback (most recent call last):
  File "/Library/Frameworks/Python.framework/Versions/3.10/lib/python3.10/site-packages/py4j/clientserver.py", line 516, in send_command
    raise Py4JNetworkError("Answer from Java side is empty")
py4j.protocol.Py4JNetworkError: Answer from Java side is empty

During handling of the above exception, another exception occurred:

Traceback (most recent call last):
  File "/Library/Frameworks/Python.framework/Versions/3.10/lib/python3.10/site-packages/py4j/java_gateway.py", line 1038, in send_command
    response = connection.send_command(command)
  File "/Library/Frameworks/Python.framework/Versions/3.10/lib/python3.10/site-packages/py4j/clientserver.py", line 539, in send_command
    raise Py4JNetworkError(
py4j.protocol.Py4JNetworkError: Error while sending or receiving
[2023-01-15T10:45:10.271+0200] {clientserver.py:543} INFO - Closing down clientserver connection
[2023-01-15T10:45:10.277+0200] {taskinstance.py:1772} ERROR - Task failed with exception
Traceback (most recent call last):
  File "/Library/Frameworks/Python.framework/Versions/3.10/lib/python3.10/site-packages/airflow/decorators/base.py", line 217, in execute
    return_value = super().execute(context)
  File "/Library/Frameworks/Python.framework/Versions/3.10/lib/python3.10/site-packages/airflow/operators/python.py", line 175, in execute
    return_value = self.execute_callable()
  File "/Library/Frameworks/Python.framework/Versions/3.10/lib/python3.10/site-packages/airflow/operators/python.py", line 192, in execute_callable
    return self.python_callable(*self.op_args, **self.op_kwargs)
  File "/Users/nhanchau/gitRepo/Raiway_with_AIrflow/dags/fetching_api.py", line 43, in etl_pipeline
    df_dict = {k: spark.createDataFrame(json.loads(v)) for (k,v) in res_dict.items()}
  File "/Users/nhanchau/gitRepo/Raiway_with_AIrflow/dags/fetching_api.py", line 43, in <dictcomp>
    df_dict = {k: spark.createDataFrame(json.loads(v)) for (k,v) in res_dict.items()}
  File "/Library/Frameworks/Python.framework/Versions/3.10/lib/python3.10/site-packages/pyspark/sql/session.py", line 873, in createDataFrame
    self._jvm.SparkSession.setActiveSession(self._jsparkSession)
  File "/Library/Frameworks/Python.framework/Versions/3.10/lib/python3.10/site-packages/py4j/java_gateway.py", line 1547, in __getattr__
    raise Py4JError(
py4j.protocol.Py4JError: org.apache.spark.sql.SparkSession.setActiveSession does not exist in the JVM
[2023-01-15T10:45:10.352+0200] {taskinstance.py:1322} INFO - Marking task as UP_FOR_RETRY. dag_id=railway_v02, task_id=etl_pipeline, execution_date=20221223T000000, start_date=20230115T084117, end_date=20230115T084510
[2023-01-15T10:45:10.400+0200] {standard_task_runner.py:100} ERROR - Failed to execute job 390 for task etl_pipeline (org.apache.spark.sql.SparkSession.setActiveSession does not exist in the JVM; 26241)
