[2023-01-15T12:25:06.928+0200] {taskinstance.py:1087} INFO - Dependencies all met for <TaskInstance: railway_v02.etl_pipeline scheduled__2022-12-27T00:00:00+00:00 [queued]>
[2023-01-15T12:25:06.944+0200] {taskinstance.py:1087} INFO - Dependencies all met for <TaskInstance: railway_v02.etl_pipeline scheduled__2022-12-27T00:00:00+00:00 [queued]>
[2023-01-15T12:25:06.945+0200] {taskinstance.py:1283} INFO - 
--------------------------------------------------------------------------------
[2023-01-15T12:25:06.946+0200] {taskinstance.py:1284} INFO - Starting attempt 7 of 6
[2023-01-15T12:25:06.946+0200] {taskinstance.py:1285} INFO - 
--------------------------------------------------------------------------------
[2023-01-15T12:25:06.959+0200] {taskinstance.py:1304} INFO - Executing <Task(_PythonDecoratedOperator): etl_pipeline> on 2022-12-27 00:00:00+00:00
[2023-01-15T12:25:06.975+0200] {standard_task_runner.py:55} INFO - Started process 43094 to run task
[2023-01-15T12:25:06.987+0200] {standard_task_runner.py:82} INFO - Running: ['airflow', 'tasks', 'run', 'railway_v02', 'etl_pipeline', 'scheduled__2022-12-27T00:00:00+00:00', '--job-id', '509', '--raw', '--subdir', 'DAGS_FOLDER/fetching_api.py', '--cfg-path', '/var/folders/qr/k2__dmk5697g2jyd7w2tpyt80000gn/T/tmprwp5ou6f']
[2023-01-15T12:25:06.994+0200] {standard_task_runner.py:83} INFO - Job 509: Subtask etl_pipeline
[2023-01-15T12:25:07.080+0200] {task_command.py:389} INFO - Running <TaskInstance: railway_v02.etl_pipeline scheduled__2022-12-27T00:00:00+00:00 [running]> on host nhanchaus-macbook-air.local
[2023-01-15T12:25:07.162+0200] {taskinstance.py:1511} INFO - Exporting the following env vars:
AIRFLOW_CTX_DAG_OWNER=Nhan_Chau
AIRFLOW_CTX_DAG_ID=railway_v02
AIRFLOW_CTX_TASK_ID=etl_pipeline
AIRFLOW_CTX_EXECUTION_DATE=2022-12-27T00:00:00+00:00
AIRFLOW_CTX_TRY_NUMBER=7
AIRFLOW_CTX_DAG_RUN_ID=scheduled__2022-12-27T00:00:00+00:00
[2023-01-15T12:25:22.203+0200] {local_task_job.py:223} WARNING - State of this instance has been externally set to failed. Terminating instance.
[2023-01-15T12:25:22.211+0200] {process_utils.py:129} INFO - Sending Signals.SIGTERM to group 43094. PIDs of all processes in the group: [43102, 43094]
[2023-01-15T12:25:22.212+0200] {process_utils.py:84} INFO - Sending the signal Signals.SIGTERM to group 43094
[2023-01-15T12:25:22.213+0200] {taskinstance.py:1483} ERROR - Received SIGTERM. Terminating subprocesses.
[2023-01-15T12:25:22.216+0200] {clientserver.py:538} INFO - Error while receiving.
Traceback (most recent call last):
  File "/Library/Frameworks/Python.framework/Versions/3.10/lib/python3.10/site-packages/py4j/clientserver.py", line 511, in send_command
    answer = smart_decode(self.stream.readline()[:-1])
  File "/Library/Frameworks/Python.framework/Versions/3.10/lib/python3.10/socket.py", line 705, in readinto
    return self._sock.recv_into(b)
  File "/Library/Frameworks/Python.framework/Versions/3.10/lib/python3.10/site-packages/airflow/models/taskinstance.py", line 1485, in signal_handler
    raise AirflowException("Task received SIGTERM signal")
airflow.exceptions.AirflowException: Task received SIGTERM signal
[2023-01-15T12:25:22.222+0200] {clientserver.py:543} INFO - Closing down clientserver connection
[2023-01-15T12:25:22.223+0200] {java_gateway.py:1055} ERROR - Exception while sending command.
Traceback (most recent call last):
  File "/Library/Frameworks/Python.framework/Versions/3.10/lib/python3.10/site-packages/py4j/clientserver.py", line 511, in send_command
    answer = smart_decode(self.stream.readline()[:-1])
  File "/Library/Frameworks/Python.framework/Versions/3.10/lib/python3.10/socket.py", line 705, in readinto
    return self._sock.recv_into(b)
  File "/Library/Frameworks/Python.framework/Versions/3.10/lib/python3.10/site-packages/airflow/models/taskinstance.py", line 1485, in signal_handler
    raise AirflowException("Task received SIGTERM signal")
airflow.exceptions.AirflowException: Task received SIGTERM signal

During handling of the above exception, another exception occurred:

Traceback (most recent call last):
  File "/Library/Frameworks/Python.framework/Versions/3.10/lib/python3.10/site-packages/py4j/java_gateway.py", line 1038, in send_command
    response = connection.send_command(command)
  File "/Library/Frameworks/Python.framework/Versions/3.10/lib/python3.10/site-packages/py4j/clientserver.py", line 539, in send_command
    raise Py4JNetworkError(
py4j.protocol.Py4JNetworkError: Error while sending or receiving
[2023-01-15T12:25:22.225+0200] {clientserver.py:543} INFO - Closing down clientserver connection
[2023-01-15T12:25:22.226+0200] {taskinstance.py:1772} ERROR - Task failed with exception
Traceback (most recent call last):
  File "/Library/Frameworks/Python.framework/Versions/3.10/lib/python3.10/site-packages/airflow/decorators/base.py", line 217, in execute
    return_value = super().execute(context)
  File "/Library/Frameworks/Python.framework/Versions/3.10/lib/python3.10/site-packages/airflow/operators/python.py", line 175, in execute
    return_value = self.execute_callable()
  File "/Library/Frameworks/Python.framework/Versions/3.10/lib/python3.10/site-packages/airflow/operators/python.py", line 192, in execute_callable
    return self.python_callable(*self.op_args, **self.op_kwargs)
  File "/Users/nhanchau/gitRepo/Raiway_with_AIrflow/dags/fetching_api.py", line 44, in etl_pipeline
    df_dict = {k: spark.createDataFrame(json.loads(v)) for (k,v) in res_dict.items()}
  File "/Users/nhanchau/gitRepo/Raiway_with_AIrflow/dags/fetching_api.py", line 44, in <dictcomp>
    df_dict = {k: spark.createDataFrame(json.loads(v)) for (k,v) in res_dict.items()}
  File "/Library/Frameworks/Python.framework/Versions/3.10/lib/python3.10/site-packages/pyspark/sql/session.py", line 894, in createDataFrame
    return self._create_dataframe(
  File "/Library/Frameworks/Python.framework/Versions/3.10/lib/python3.10/site-packages/pyspark/sql/session.py", line 939, in _create_dataframe
    jdf = self._jsparkSession.applySchemaToPythonRDD(jrdd.rdd(), struct.json())
  File "/Library/Frameworks/Python.framework/Versions/3.10/lib/python3.10/site-packages/py4j/java_gateway.py", line 1321, in __call__
    return_value = get_return_value(
  File "/Library/Frameworks/Python.framework/Versions/3.10/lib/python3.10/site-packages/pyspark/sql/utils.py", line 190, in deco
    return f(*a, **kw)
  File "/Library/Frameworks/Python.framework/Versions/3.10/lib/python3.10/site-packages/py4j/protocol.py", line 334, in get_return_value
    raise Py4JError(
py4j.protocol.Py4JError: An error occurred while calling o28.applySchemaToPythonRDD
[2023-01-15T12:25:22.248+0200] {taskinstance.py:1322} INFO - Marking task as FAILED. dag_id=railway_v02, task_id=etl_pipeline, execution_date=20221227T000000, start_date=20230115T102506, end_date=20230115T102522
[2023-01-15T12:25:22.280+0200] {standard_task_runner.py:100} ERROR - Failed to execute job 509 for task etl_pipeline (An error occurred while calling o28.applySchemaToPythonRDD; 43094)
[2023-01-15T12:25:22.350+0200] {process_utils.py:79} INFO - Process psutil.Process(pid=43094, status='terminated', exitcode=1, started='12:25:06') (43094) terminated with exit code 1
[2023-01-15T12:25:23.039+0200] {process_utils.py:79} INFO - Process psutil.Process(pid=43102, status='terminated', started='12:25:07') (43102) terminated with exit code None
