[2023-01-15T09:41:53.475+0200] {taskinstance.py:1087} INFO - Dependencies all met for <TaskInstance: railway_v02.etl_pipeline scheduled__2022-12-27T00:00:00+00:00 [queued]>
[2023-01-15T09:41:54.218+0200] {taskinstance.py:1087} INFO - Dependencies all met for <TaskInstance: railway_v02.etl_pipeline scheduled__2022-12-27T00:00:00+00:00 [queued]>
[2023-01-15T09:41:54.243+0200] {taskinstance.py:1283} INFO - 
--------------------------------------------------------------------------------
[2023-01-15T09:41:54.251+0200] {taskinstance.py:1284} INFO - Starting attempt 1 of 6
[2023-01-15T09:41:54.254+0200] {taskinstance.py:1285} INFO - 
--------------------------------------------------------------------------------
[2023-01-15T09:41:54.807+0200] {taskinstance.py:1304} INFO - Executing <Task(_PythonDecoratedOperator): etl_pipeline> on 2022-12-27 00:00:00+00:00
[2023-01-15T09:41:55.298+0200] {standard_task_runner.py:55} INFO - Started process 31113 to run task
[2023-01-15T09:41:55.429+0200] {standard_task_runner.py:82} INFO - Running: ['airflow', 'tasks', 'run', 'railway_v02', 'etl_pipeline', 'scheduled__2022-12-27T00:00:00+00:00', '--job-id', '243', '--raw', '--subdir', 'DAGS_FOLDER/fetching_api.py', '--cfg-path', '/var/folders/qr/k2__dmk5697g2jyd7w2tpyt80000gn/T/tmpg9jj06q1']
[2023-01-15T09:41:55.484+0200] {standard_task_runner.py:83} INFO - Job 243: Subtask etl_pipeline
[2023-01-15T09:41:59.065+0200] {task_command.py:389} INFO - Running <TaskInstance: railway_v02.etl_pipeline scheduled__2022-12-27T00:00:00+00:00 [running]> on host nhanchaus-macbook-air.local
[2023-01-15T09:42:03.274+0200] {taskinstance.py:1511} INFO - Exporting the following env vars:
AIRFLOW_CTX_DAG_OWNER=Nhan_Chau
AIRFLOW_CTX_DAG_ID=railway_v02
AIRFLOW_CTX_TASK_ID=etl_pipeline
AIRFLOW_CTX_EXECUTION_DATE=2022-12-27T00:00:00+00:00
AIRFLOW_CTX_TRY_NUMBER=1
AIRFLOW_CTX_DAG_RUN_ID=scheduled__2022-12-27T00:00:00+00:00
[2023-01-15T11:12:45.811+0200] {taskinstance.py:1087} INFO - Dependencies all met for <TaskInstance: railway_v02.etl_pipeline scheduled__2022-12-27T00:00:00+00:00 [queued]>
[2023-01-15T11:12:45.829+0200] {taskinstance.py:1087} INFO - Dependencies all met for <TaskInstance: railway_v02.etl_pipeline scheduled__2022-12-27T00:00:00+00:00 [queued]>
[2023-01-15T11:12:45.830+0200] {taskinstance.py:1283} INFO - 
--------------------------------------------------------------------------------
[2023-01-15T11:12:45.830+0200] {taskinstance.py:1284} INFO - Starting attempt 1 of 6
[2023-01-15T11:12:45.831+0200] {taskinstance.py:1285} INFO - 
--------------------------------------------------------------------------------
[2023-01-15T11:12:45.844+0200] {taskinstance.py:1304} INFO - Executing <Task(_PythonDecoratedOperator): etl_pipeline> on 2022-12-27 00:00:00+00:00
[2023-01-15T11:12:45.855+0200] {standard_task_runner.py:55} INFO - Started process 9616 to run task
[2023-01-15T11:12:45.863+0200] {standard_task_runner.py:82} INFO - Running: ['airflow', 'tasks', 'run', 'railway_v02', 'etl_pipeline', 'scheduled__2022-12-27T00:00:00+00:00', '--job-id', '438', '--raw', '--subdir', 'DAGS_FOLDER/fetching_api.py', '--cfg-path', '/var/folders/qr/k2__dmk5697g2jyd7w2tpyt80000gn/T/tmpnj02at2g']
[2023-01-15T11:12:45.866+0200] {standard_task_runner.py:83} INFO - Job 438: Subtask etl_pipeline
[2023-01-15T11:12:46.007+0200] {task_command.py:389} INFO - Running <TaskInstance: railway_v02.etl_pipeline scheduled__2022-12-27T00:00:00+00:00 [running]> on host nhanchaus-macbook-air.local
[2023-01-15T11:12:46.095+0200] {taskinstance.py:1511} INFO - Exporting the following env vars:
AIRFLOW_CTX_DAG_OWNER=Nhan_Chau
AIRFLOW_CTX_DAG_ID=railway_v02
AIRFLOW_CTX_TASK_ID=etl_pipeline
AIRFLOW_CTX_EXECUTION_DATE=2022-12-27T00:00:00+00:00
AIRFLOW_CTX_TRY_NUMBER=1
AIRFLOW_CTX_DAG_RUN_ID=scheduled__2022-12-27T00:00:00+00:00
[2023-01-15T11:13:45.776+0200] {taskinstance.py:1772} ERROR - Task failed with exception
Traceback (most recent call last):
  File "/Library/Frameworks/Python.framework/Versions/3.10/lib/python3.10/site-packages/airflow/decorators/base.py", line 217, in execute
    return_value = super().execute(context)
  File "/Library/Frameworks/Python.framework/Versions/3.10/lib/python3.10/site-packages/airflow/operators/python.py", line 175, in execute
    return_value = self.execute_callable()
  File "/Library/Frameworks/Python.framework/Versions/3.10/lib/python3.10/site-packages/airflow/operators/python.py", line 192, in execute_callable
    return self.python_callable(*self.op_args, **self.op_kwargs)
  File "/Users/nhanchau/gitRepo/Raiway_with_AIrflow/dags/fetching_api.py", line 108, in etl_pipeline
    (v
  File "/Library/Frameworks/Python.framework/Versions/3.10/lib/python3.10/site-packages/pyspark/sql/readwriter.py", line 1340, in jdbc
    self.mode(mode)._jwrite.jdbc(url, table, jprop)
  File "/Library/Frameworks/Python.framework/Versions/3.10/lib/python3.10/site-packages/py4j/java_gateway.py", line 1321, in __call__
    return_value = get_return_value(
  File "/Library/Frameworks/Python.framework/Versions/3.10/lib/python3.10/site-packages/pyspark/sql/utils.py", line 190, in deco
    return f(*a, **kw)
  File "/Library/Frameworks/Python.framework/Versions/3.10/lib/python3.10/site-packages/py4j/protocol.py", line 326, in get_return_value
    raise Py4JJavaError(
py4j.protocol.Py4JJavaError: An error occurred while calling o219.jdbc.
: org.apache.spark.SparkException: Job aborted due to stage failure: Task 2 in stage 7.0 failed 1 times, most recent failure: Lost task 2.0 in stage 7.0 (TID 28) (192.168.0.3 executor driver): java.sql.BatchUpdateException: Batch entry 0 INSERT INTO category_res ("name") VALUES ('Commuter') was aborted: ERROR: relation "category_res" does not exist
  Position: 13  Call getNextException to see other errors in the batch.
	at org.postgresql.jdbc.BatchResultHandler.handleError(BatchResultHandler.java:165)
	at org.postgresql.core.ResultHandlerDelegate.handleError(ResultHandlerDelegate.java:52)
	at org.postgresql.core.v3.QueryExecutorImpl.processResults(QueryExecutorImpl.java:2367)
	at org.postgresql.core.v3.QueryExecutorImpl.execute(QueryExecutorImpl.java:560)
	at org.postgresql.jdbc.PgStatement.internalExecuteBatch(PgStatement.java:893)
	at org.postgresql.jdbc.PgStatement.executeBatch(PgStatement.java:916)
	at org.postgresql.jdbc.PgPreparedStatement.executeBatch(PgPreparedStatement.java:1684)
	at org.apache.spark.sql.execution.datasources.jdbc.JdbcUtils$.savePartition(JdbcUtils.scala:713)
	at org.apache.spark.sql.execution.datasources.jdbc.JdbcUtils$.$anonfun$saveTable$1(JdbcUtils.scala:868)
	at org.apache.spark.sql.execution.datasources.jdbc.JdbcUtils$.$anonfun$saveTable$1$adapted(JdbcUtils.scala:867)
	at org.apache.spark.rdd.RDD.$anonfun$foreachPartition$2(RDD.scala:1011)
	at org.apache.spark.rdd.RDD.$anonfun$foreachPartition$2$adapted(RDD.scala:1011)
	at org.apache.spark.SparkContext.$anonfun$runJob$5(SparkContext.scala:2268)
	at org.apache.spark.scheduler.ResultTask.runTask(ResultTask.scala:90)
	at org.apache.spark.scheduler.Task.run(Task.scala:136)
	at org.apache.spark.executor.Executor$TaskRunner.$anonfun$run$3(Executor.scala:548)
	at org.apache.spark.util.Utils$.tryWithSafeFinally(Utils.scala:1504)
	at org.apache.spark.executor.Executor$TaskRunner.run(Executor.scala:551)
	at java.base/java.util.concurrent.ThreadPoolExecutor.runWorker(ThreadPoolExecutor.java:1144)
	at java.base/java.util.concurrent.ThreadPoolExecutor$Worker.run(ThreadPoolExecutor.java:642)
	at java.base/java.lang.Thread.run(Thread.java:1589)
Caused by: org.postgresql.util.PSQLException: ERROR: relation "category_res" does not exist
  Position: 13
	at org.postgresql.core.v3.QueryExecutorImpl.receiveErrorResponse(QueryExecutorImpl.java:2676)
	at org.postgresql.core.v3.QueryExecutorImpl.processResults(QueryExecutorImpl.java:2366)
	... 18 more

Driver stacktrace:
	at org.apache.spark.scheduler.DAGScheduler.failJobAndIndependentStages(DAGScheduler.scala:2672)
	at org.apache.spark.scheduler.DAGScheduler.$anonfun$abortStage$2(DAGScheduler.scala:2608)
	at org.apache.spark.scheduler.DAGScheduler.$anonfun$abortStage$2$adapted(DAGScheduler.scala:2607)
	at scala.collection.mutable.ResizableArray.foreach(ResizableArray.scala:62)
	at scala.collection.mutable.ResizableArray.foreach$(ResizableArray.scala:55)
	at scala.collection.mutable.ArrayBuffer.foreach(ArrayBuffer.scala:49)
	at org.apache.spark.scheduler.DAGScheduler.abortStage(DAGScheduler.scala:2607)
	at org.apache.spark.scheduler.DAGScheduler.$anonfun$handleTaskSetFailed$1(DAGScheduler.scala:1182)
	at org.apache.spark.scheduler.DAGScheduler.$anonfun$handleTaskSetFailed$1$adapted(DAGScheduler.scala:1182)
	at scala.Option.foreach(Option.scala:407)
	at org.apache.spark.scheduler.DAGScheduler.handleTaskSetFailed(DAGScheduler.scala:1182)
	at org.apache.spark.scheduler.DAGSchedulerEventProcessLoop.doOnReceive(DAGScheduler.scala:2860)
	at org.apache.spark.scheduler.DAGSchedulerEventProcessLoop.onReceive(DAGScheduler.scala:2802)
	at org.apache.spark.scheduler.DAGSchedulerEventProcessLoop.onReceive(DAGScheduler.scala:2791)
	at org.apache.spark.util.EventLoop$$anon$1.run(EventLoop.scala:49)
	at org.apache.spark.scheduler.DAGScheduler.runJob(DAGScheduler.scala:952)
	at org.apache.spark.SparkContext.runJob(SparkContext.scala:2228)
	at org.apache.spark.SparkContext.runJob(SparkContext.scala:2249)
	at org.apache.spark.SparkContext.runJob(SparkContext.scala:2268)
	at org.apache.spark.SparkContext.runJob(SparkContext.scala:2293)
	at org.apache.spark.rdd.RDD.$anonfun$foreachPartition$1(RDD.scala:1011)
	at org.apache.spark.rdd.RDDOperationScope$.withScope(RDDOperationScope.scala:151)
	at org.apache.spark.rdd.RDDOperationScope$.withScope(RDDOperationScope.scala:112)
	at org.apache.spark.rdd.RDD.withScope(RDD.scala:406)
	at org.apache.spark.rdd.RDD.foreachPartition(RDD.scala:1009)
	at org.apache.spark.sql.execution.datasources.jdbc.JdbcUtils$.saveTable(JdbcUtils.scala:867)
	at org.apache.spark.sql.execution.datasources.jdbc.JdbcRelationProvider.createRelation(JdbcRelationProvider.scala:65)
	at org.apache.spark.sql.execution.datasources.SaveIntoDataSourceCommand.run(SaveIntoDataSourceCommand.scala:47)
	at org.apache.spark.sql.execution.command.ExecutedCommandExec.sideEffectResult$lzycompute(commands.scala:75)
	at org.apache.spark.sql.execution.command.ExecutedCommandExec.sideEffectResult(commands.scala:73)
	at org.apache.spark.sql.execution.command.ExecutedCommandExec.executeCollect(commands.scala:84)
	at org.apache.spark.sql.execution.QueryExecution$$anonfun$eagerlyExecuteCommands$1.$anonfun$applyOrElse$1(QueryExecution.scala:98)
	at org.apache.spark.sql.execution.SQLExecution$.$anonfun$withNewExecutionId$6(SQLExecution.scala:109)
	at org.apache.spark.sql.execution.SQLExecution$.withSQLConfPropagated(SQLExecution.scala:169)
	at org.apache.spark.sql.execution.SQLExecution$.$anonfun$withNewExecutionId$1(SQLExecution.scala:95)
	at org.apache.spark.sql.SparkSession.withActive(SparkSession.scala:779)
	at org.apache.spark.sql.execution.SQLExecution$.withNewExecutionId(SQLExecution.scala:64)
	at org.apache.spark.sql.execution.QueryExecution$$anonfun$eagerlyExecuteCommands$1.applyOrElse(QueryExecution.scala:98)
	at org.apache.spark.sql.execution.QueryExecution$$anonfun$eagerlyExecuteCommands$1.applyOrElse(QueryExecution.scala:94)
	at org.apache.spark.sql.catalyst.trees.TreeNode.$anonfun$transformDownWithPruning$1(TreeNode.scala:584)
	at org.apache.spark.sql.catalyst.trees.CurrentOrigin$.withOrigin(TreeNode.scala:176)
	at org.apache.spark.sql.catalyst.trees.TreeNode.transformDownWithPruning(TreeNode.scala:584)
	at org.apache.spark.sql.catalyst.plans.logical.LogicalPlan.org$apache$spark$sql$catalyst$plans$logical$AnalysisHelper$$super$transformDownWithPruning(LogicalPlan.scala:30)
	at org.apache.spark.sql.catalyst.plans.logical.AnalysisHelper.transformDownWithPruning(AnalysisHelper.scala:267)
	at org.apache.spark.sql.catalyst.plans.logical.AnalysisHelper.transformDownWithPruning$(AnalysisHelper.scala:263)
	at org.apache.spark.sql.catalyst.plans.logical.LogicalPlan.transformDownWithPruning(LogicalPlan.scala:30)
	at org.apache.spark.sql.catalyst.plans.logical.LogicalPlan.transformDownWithPruning(LogicalPlan.scala:30)
	at org.apache.spark.sql.catalyst.trees.TreeNode.transformDown(TreeNode.scala:560)
	at org.apache.spark.sql.execution.QueryExecution.eagerlyExecuteCommands(QueryExecution.scala:94)
	at org.apache.spark.sql.execution.QueryExecution.commandExecuted$lzycompute(QueryExecution.scala:81)
	at org.apache.spark.sql.execution.QueryExecution.commandExecuted(QueryExecution.scala:79)
	at org.apache.spark.sql.execution.QueryExecution.assertCommandExecuted(QueryExecution.scala:116)
	at org.apache.spark.sql.DataFrameWriter.runCommand(DataFrameWriter.scala:860)
	at org.apache.spark.sql.DataFrameWriter.saveToV1Source(DataFrameWriter.scala:390)
	at org.apache.spark.sql.DataFrameWriter.saveInternal(DataFrameWriter.scala:363)
	at org.apache.spark.sql.DataFrameWriter.save(DataFrameWriter.scala:247)
	at org.apache.spark.sql.DataFrameWriter.jdbc(DataFrameWriter.scala:757)
	at java.base/jdk.internal.reflect.DirectMethodHandleAccessor.invoke(DirectMethodHandleAccessor.java:104)
	at java.base/java.lang.reflect.Method.invoke(Method.java:578)
	at py4j.reflection.MethodInvoker.invoke(MethodInvoker.java:244)
	at py4j.reflection.ReflectionEngine.invoke(ReflectionEngine.java:357)
	at py4j.Gateway.invoke(Gateway.java:282)
	at py4j.commands.AbstractCommand.invokeMethod(AbstractCommand.java:132)
	at py4j.commands.CallCommand.execute(CallCommand.java:79)
	at py4j.ClientServerConnection.waitForCommands(ClientServerConnection.java:182)
	at py4j.ClientServerConnection.run(ClientServerConnection.java:106)
	at java.base/java.lang.Thread.run(Thread.java:1589)
Caused by: java.sql.BatchUpdateException: Batch entry 0 INSERT INTO category_res ("name") VALUES ('Commuter') was aborted: ERROR: relation "category_res" does not exist
  Position: 13  Call getNextException to see other errors in the batch.
	at org.postgresql.jdbc.BatchResultHandler.handleError(BatchResultHandler.java:165)
	at org.postgresql.core.ResultHandlerDelegate.handleError(ResultHandlerDelegate.java:52)
	at org.postgresql.core.v3.QueryExecutorImpl.processResults(QueryExecutorImpl.java:2367)
	at org.postgresql.core.v3.QueryExecutorImpl.execute(QueryExecutorImpl.java:560)
	at org.postgresql.jdbc.PgStatement.internalExecuteBatch(PgStatement.java:893)
	at org.postgresql.jdbc.PgStatement.executeBatch(PgStatement.java:916)
	at org.postgresql.jdbc.PgPreparedStatement.executeBatch(PgPreparedStatement.java:1684)
	at org.apache.spark.sql.execution.datasources.jdbc.JdbcUtils$.savePartition(JdbcUtils.scala:713)
	at org.apache.spark.sql.execution.datasources.jdbc.JdbcUtils$.$anonfun$saveTable$1(JdbcUtils.scala:868)
	at org.apache.spark.sql.execution.datasources.jdbc.JdbcUtils$.$anonfun$saveTable$1$adapted(JdbcUtils.scala:867)
	at org.apache.spark.rdd.RDD.$anonfun$foreachPartition$2(RDD.scala:1011)
	at org.apache.spark.rdd.RDD.$anonfun$foreachPartition$2$adapted(RDD.scala:1011)
	at org.apache.spark.SparkContext.$anonfun$runJob$5(SparkContext.scala:2268)
	at org.apache.spark.scheduler.ResultTask.runTask(ResultTask.scala:90)
	at org.apache.spark.scheduler.Task.run(Task.scala:136)
	at org.apache.spark.executor.Executor$TaskRunner.$anonfun$run$3(Executor.scala:548)
	at org.apache.spark.util.Utils$.tryWithSafeFinally(Utils.scala:1504)
	at org.apache.spark.executor.Executor$TaskRunner.run(Executor.scala:551)
	at java.base/java.util.concurrent.ThreadPoolExecutor.runWorker(ThreadPoolExecutor.java:1144)
	at java.base/java.util.concurrent.ThreadPoolExecutor$Worker.run(ThreadPoolExecutor.java:642)
	... 1 more
Caused by: org.postgresql.util.PSQLException: ERROR: relation "category_res" does not exist
  Position: 13
	at org.postgresql.core.v3.QueryExecutorImpl.receiveErrorResponse(QueryExecutorImpl.java:2676)
	at org.postgresql.core.v3.QueryExecutorImpl.processResults(QueryExecutorImpl.java:2366)
	... 18 more

[2023-01-15T11:13:46.979+0200] {taskinstance.py:1322} INFO - Marking task as UP_FOR_RETRY. dag_id=railway_v02, task_id=etl_pipeline, execution_date=20221227T000000, start_date=20230115T091245, end_date=20230115T091346
[2023-01-15T11:13:50.448+0200] {standard_task_runner.py:100} ERROR - Failed to execute job 438 for task etl_pipeline (An error occurred while calling o219.jdbc.
: org.apache.spark.SparkException: Job aborted due to stage failure: Task 2 in stage 7.0 failed 1 times, most recent failure: Lost task 2.0 in stage 7.0 (TID 28) (192.168.0.3 executor driver): java.sql.BatchUpdateException: Batch entry 0 INSERT INTO category_res ("name") VALUES ('Commuter') was aborted: ERROR: relation "category_res" does not exist
  Position: 13  Call getNextException to see other errors in the batch.
	at org.postgresql.jdbc.BatchResultHandler.handleError(BatchResultHandler.java:165)
	at org.postgresql.core.ResultHandlerDelegate.handleError(ResultHandlerDelegate.java:52)
	at org.postgresql.core.v3.QueryExecutorImpl.processResults(QueryExecutorImpl.java:2367)
	at org.postgresql.core.v3.QueryExecutorImpl.execute(QueryExecutorImpl.java:560)
	at org.postgresql.jdbc.PgStatement.internalExecuteBatch(PgStatement.java:893)
	at org.postgresql.jdbc.PgStatement.executeBatch(PgStatement.java:916)
	at org.postgresql.jdbc.PgPreparedStatement.executeBatch(PgPreparedStatement.java:1684)
	at org.apache.spark.sql.execution.datasources.jdbc.JdbcUtils$.savePartition(JdbcUtils.scala:713)
	at org.apache.spark.sql.execution.datasources.jdbc.JdbcUtils$.$anonfun$saveTable$1(JdbcUtils.scala:868)
	at org.apache.spark.sql.execution.datasources.jdbc.JdbcUtils$.$anonfun$saveTable$1$adapted(JdbcUtils.scala:867)
	at org.apache.spark.rdd.RDD.$anonfun$foreachPartition$2(RDD.scala:1011)
	at org.apache.spark.rdd.RDD.$anonfun$foreachPartition$2$adapted(RDD.scala:1011)
	at org.apache.spark.SparkContext.$anonfun$runJob$5(SparkContext.scala:2268)
	at org.apache.spark.scheduler.ResultTask.runTask(ResultTask.scala:90)
	at org.apache.spark.scheduler.Task.run(Task.scala:136)
	at org.apache.spark.executor.Executor$TaskRunner.$anonfun$run$3(Executor.scala:548)
	at org.apache.spark.util.Utils$.tryWithSafeFinally(Utils.scala:1504)
	at org.apache.spark.executor.Executor$TaskRunner.run(Executor.scala:551)
	at java.base/java.util.concurrent.ThreadPoolExecutor.runWorker(ThreadPoolExecutor.java:1144)
	at java.base/java.util.concurrent.ThreadPoolExecutor$Worker.run(ThreadPoolExecutor.java:642)
	at java.base/java.lang.Thread.run(Thread.java:1589)
Caused by: org.postgresql.util.PSQLException: ERROR: relation "category_res" does not exist
  Position: 13
	at org.postgresql.core.v3.QueryExecutorImpl.receiveErrorResponse(QueryExecutorImpl.java:2676)
	at org.postgresql.core.v3.QueryExecutorImpl.processResults(QueryExecutorImpl.java:2366)
	... 18 more

Driver stacktrace:
	at org.apache.spark.scheduler.DAGScheduler.failJobAndIndependentStages(DAGScheduler.scala:2672)
	at org.apache.spark.scheduler.DAGScheduler.$anonfun$abortStage$2(DAGScheduler.scala:2608)
	at org.apache.spark.scheduler.DAGScheduler.$anonfun$abortStage$2$adapted(DAGScheduler.scala:2607)
	at scala.collection.mutable.ResizableArray.foreach(ResizableArray.scala:62)
	at scala.collection.mutable.ResizableArray.foreach$(ResizableArray.scala:55)
	at scala.collection.mutable.ArrayBuffer.foreach(ArrayBuffer.scala:49)
	at org.apache.spark.scheduler.DAGScheduler.abortStage(DAGScheduler.scala:2607)
	at org.apache.spark.scheduler.DAGScheduler.$anonfun$handleTaskSetFailed$1(DAGScheduler.scala:1182)
	at org.apache.spark.scheduler.DAGScheduler.$anonfun$handleTaskSetFailed$1$adapted(DAGScheduler.scala:1182)
	at scala.Option.foreach(Option.scala:407)
	at org.apache.spark.scheduler.DAGScheduler.handleTaskSetFailed(DAGScheduler.scala:1182)
	at org.apache.spark.scheduler.DAGSchedulerEventProcessLoop.doOnReceive(DAGScheduler.scala:2860)
	at org.apache.spark.scheduler.DAGSchedulerEventProcessLoop.onReceive(DAGScheduler.scala:2802)
	at org.apache.spark.scheduler.DAGSchedulerEventProcessLoop.onReceive(DAGScheduler.scala:2791)
	at org.apache.spark.util.EventLoop$$anon$1.run(EventLoop.scala:49)
	at org.apache.spark.scheduler.DAGScheduler.runJob(DAGScheduler.scala:952)
	at org.apache.spark.SparkContext.runJob(SparkContext.scala:2228)
	at org.apache.spark.SparkContext.runJob(SparkContext.scala:2249)
	at org.apache.spark.SparkContext.runJob(SparkContext.scala:2268)
	at org.apache.spark.SparkContext.runJob(SparkContext.scala:2293)
	at org.apache.spark.rdd.RDD.$anonfun$foreachPartition$1(RDD.scala:1011)
	at org.apache.spark.rdd.RDDOperationScope$.withScope(RDDOperationScope.scala:151)
	at org.apache.spark.rdd.RDDOperationScope$.withScope(RDDOperationScope.scala:112)
	at org.apache.spark.rdd.RDD.withScope(RDD.scala:406)
	at org.apache.spark.rdd.RDD.foreachPartition(RDD.scala:1009)
	at org.apache.spark.sql.execution.datasources.jdbc.JdbcUtils$.saveTable(JdbcUtils.scala:867)
	at org.apache.spark.sql.execution.datasources.jdbc.JdbcRelationProvider.createRelation(JdbcRelationProvider.scala:65)
	at org.apache.spark.sql.execution.datasources.SaveIntoDataSourceCommand.run(SaveIntoDataSourceCommand.scala:47)
	at org.apache.spark.sql.execution.command.ExecutedCommandExec.sideEffectResult$lzycompute(commands.scala:75)
	at org.apache.spark.sql.execution.command.ExecutedCommandExec.sideEffectResult(commands.scala:73)
	at org.apache.spark.sql.execution.command.ExecutedCommandExec.executeCollect(commands.scala:84)
	at org.apache.spark.sql.execution.QueryExecution$$anonfun$eagerlyExecuteCommands$1.$anonfun$applyOrElse$1(QueryExecution.scala:98)
	at org.apache.spark.sql.execution.SQLExecution$.$anonfun$withNewExecutionId$6(SQLExecution.scala:109)
	at org.apache.spark.sql.execution.SQLExecution$.withSQLConfPropagated(SQLExecution.scala:169)
	at org.apache.spark.sql.execution.SQLExecution$.$anonfun$withNewExecutionId$1(SQLExecution.scala:95)
	at org.apache.spark.sql.SparkSession.withActive(SparkSession.scala:779)
	at org.apache.spark.sql.execution.SQLExecution$.withNewExecutionId(SQLExecution.scala:64)
	at org.apache.spark.sql.execution.QueryExecution$$anonfun$eagerlyExecuteCommands$1.applyOrElse(QueryExecution.scala:98)
	at org.apache.spark.sql.execution.QueryExecution$$anonfun$eagerlyExecuteCommands$1.applyOrElse(QueryExecution.scala:94)
	at org.apache.spark.sql.catalyst.trees.TreeNode.$anonfun$transformDownWithPruning$1(TreeNode.scala:584)
	at org.apache.spark.sql.catalyst.trees.CurrentOrigin$.withOrigin(TreeNode.scala:176)
	at org.apache.spark.sql.catalyst.trees.TreeNode.transformDownWithPruning(TreeNode.scala:584)
	at org.apache.spark.sql.catalyst.plans.logical.LogicalPlan.org$apache$spark$sql$catalyst$plans$logical$AnalysisHelper$$super$transformDownWithPruning(LogicalPlan.scala:30)
	at org.apache.spark.sql.catalyst.plans.logical.AnalysisHelper.transformDownWithPruning(AnalysisHelper.scala:267)
	at org.apache.spark.sql.catalyst.plans.logical.AnalysisHelper.transformDownWithPruning$(AnalysisHelper.scala:263)
	at org.apache.spark.sql.catalyst.plans.logical.LogicalPlan.transformDownWithPruning(LogicalPlan.scala:30)
	at org.apache.spark.sql.catalyst.plans.logical.LogicalPlan.transformDownWithPruning(LogicalPlan.scala:30)
	at org.apache.spark.sql.catalyst.trees.TreeNode.transformDown(TreeNode.scala:560)
	at org.apache.spark.sql.execution.QueryExecution.eagerlyExecuteCommands(QueryExecution.scala:94)
	at org.apache.spark.sql.execution.QueryExecution.commandExecuted$lzycompute(QueryExecution.scala:81)
	at org.apache.spark.sql.execution.QueryExecution.commandExecuted(QueryExecution.scala:79)
	at org.apache.spark.sql.execution.QueryExecution.assertCommandExecuted(QueryExecution.scala:116)
	at org.apache.spark.sql.DataFrameWriter.runCommand(DataFrameWriter.scala:860)
	at org.apache.spark.sql.DataFrameWriter.saveToV1Source(DataFrameWriter.scala:390)
	at org.apache.spark.sql.DataFrameWriter.saveInternal(DataFrameWriter.scala:363)
	at org.apache.spark.sql.DataFrameWriter.save(DataFrameWriter.scala:247)
	at org.apache.spark.sql.DataFrameWriter.jdbc(DataFrameWriter.scala:757)
	at java.base/jdk.internal.reflect.DirectMethodHandleAccessor.invoke(DirectMethodHandleAccessor.java:104)
	at java.base/java.lang.reflect.Method.invoke(Method.java:578)
	at py4j.reflection.MethodInvoker.invoke(MethodInvoker.java:244)
	at py4j.reflection.ReflectionEngine.invoke(ReflectionEngine.java:357)
	at py4j.Gateway.invoke(Gateway.java:282)
	at py4j.commands.AbstractCommand.invokeMethod(AbstractCommand.java:132)
	at py4j.commands.CallCommand.execute(CallCommand.java:79)
	at py4j.ClientServerConnection.waitForCommands(ClientServerConnection.java:182)
	at py4j.ClientServerConnection.run(ClientServerConnection.java:106)
	at java.base/java.lang.Thread.run(Thread.java:1589)
Caused by: java.sql.BatchUpdateException: Batch entry 0 INSERT INTO category_res ("name") VALUES ('Commuter') was aborted: ERROR: relation "category_res" does not exist
  Position: 13  Call getNextException to see other errors in the batch.
	at org.postgresql.jdbc.BatchResultHandler.handleError(BatchResultHandler.java:165)
	at org.postgresql.core.ResultHandlerDelegate.handleError(ResultHandlerDelegate.java:52)
	at org.postgresql.core.v3.QueryExecutorImpl.processResults(QueryExecutorImpl.java:2367)
	at org.postgresql.core.v3.QueryExecutorImpl.execute(QueryExecutorImpl.java:560)
	at org.postgresql.jdbc.PgStatement.internalExecuteBatch(PgStatement.java:893)
	at org.postgresql.jdbc.PgStatement.executeBatch(PgStatement.java:916)
	at org.postgresql.jdbc.PgPreparedStatement.executeBatch(PgPreparedStatement.java:1684)
	at org.apache.spark.sql.execution.datasources.jdbc.JdbcUtils$.savePartition(JdbcUtils.scala:713)
	at org.apache.spark.sql.execution.datasources.jdbc.JdbcUtils$.$anonfun$saveTable$1(JdbcUtils.scala:868)
	at org.apache.spark.sql.execution.datasources.jdbc.JdbcUtils$.$anonfun$saveTable$1$adapted(JdbcUtils.scala:867)
	at org.apache.spark.rdd.RDD.$anonfun$foreachPartition$2(RDD.scala:1011)
	at org.apache.spark.rdd.RDD.$anonfun$foreachPartition$2$adapted(RDD.scala:1011)
	at org.apache.spark.SparkContext.$anonfun$runJob$5(SparkContext.scala:2268)
	at org.apache.spark.scheduler.ResultTask.runTask(ResultTask.scala:90)
	at org.apache.spark.scheduler.Task.run(Task.scala:136)
	at org.apache.spark.executor.Executor$TaskRunner.$anonfun$run$3(Executor.scala:548)
	at org.apache.spark.util.Utils$.tryWithSafeFinally(Utils.scala:1504)
	at org.apache.spark.executor.Executor$TaskRunner.run(Executor.scala:551)
	at java.base/java.util.concurrent.ThreadPoolExecutor.runWorker(ThreadPoolExecutor.java:1144)
	at java.base/java.util.concurrent.ThreadPoolExecutor$Worker.run(ThreadPoolExecutor.java:642)
	... 1 more
Caused by: org.postgresql.util.PSQLException: ERROR: relation "category_res" does not exist
  Position: 13
	at org.postgresql.core.v3.QueryExecutorImpl.receiveErrorResponse(QueryExecutorImpl.java:2676)
	at org.postgresql.core.v3.QueryExecutorImpl.processResults(QueryExecutorImpl.java:2366)
	... 18 more
; 9616)
[2023-01-15T11:13:50.511+0200] {local_task_job.py:159} INFO - Task exited with return code 1
[2023-01-15T11:13:50.805+0200] {taskinstance.py:2582} INFO - 0 downstream tasks scheduled from follow-on schedule check
