[2023-01-15T10:11:23.148+0200] {taskinstance.py:1087} INFO - Dependencies all met for <TaskInstance: railway_v02.etl_pipeline scheduled__2022-12-27T00:00:00+00:00 [queued]>
[2023-01-15T10:11:23.280+0200] {taskinstance.py:1087} INFO - Dependencies all met for <TaskInstance: railway_v02.etl_pipeline scheduled__2022-12-27T00:00:00+00:00 [queued]>
[2023-01-15T10:11:23.285+0200] {taskinstance.py:1283} INFO - 
--------------------------------------------------------------------------------
[2023-01-15T10:11:23.288+0200] {taskinstance.py:1284} INFO - Starting attempt 3 of 6
[2023-01-15T10:11:23.302+0200] {taskinstance.py:1285} INFO - 
--------------------------------------------------------------------------------
[2023-01-15T10:11:23.478+0200] {taskinstance.py:1304} INFO - Executing <Task(_PythonDecoratedOperator): etl_pipeline> on 2022-12-27 00:00:00+00:00
[2023-01-15T10:11:23.581+0200] {standard_task_runner.py:55} INFO - Started process 13823 to run task
[2023-01-15T10:11:23.679+0200] {standard_task_runner.py:82} INFO - Running: ['airflow', 'tasks', 'run', 'railway_v02', 'etl_pipeline', 'scheduled__2022-12-27T00:00:00+00:00', '--job-id', '338', '--raw', '--subdir', 'DAGS_FOLDER/fetching_api.py', '--cfg-path', '/var/folders/qr/k2__dmk5697g2jyd7w2tpyt80000gn/T/tmpo8tdpc8_']
[2023-01-15T10:11:23.704+0200] {standard_task_runner.py:83} INFO - Job 338: Subtask etl_pipeline
[2023-01-15T10:11:24.693+0200] {task_command.py:389} INFO - Running <TaskInstance: railway_v02.etl_pipeline scheduled__2022-12-27T00:00:00+00:00 [running]> on host nhanchaus-macbook-air.local
[2023-01-15T10:11:26.441+0200] {taskinstance.py:1511} INFO - Exporting the following env vars:
AIRFLOW_CTX_DAG_OWNER=Nhan_Chau
AIRFLOW_CTX_DAG_ID=railway_v02
AIRFLOW_CTX_TASK_ID=etl_pipeline
AIRFLOW_CTX_EXECUTION_DATE=2022-12-27T00:00:00+00:00
AIRFLOW_CTX_TRY_NUMBER=3
AIRFLOW_CTX_DAG_RUN_ID=scheduled__2022-12-27T00:00:00+00:00
[2023-01-15T10:17:24.508+0200] {clientserver.py:538} INFO - Error while receiving.
Traceback (most recent call last):
  File "/Library/Frameworks/Python.framework/Versions/3.10/lib/python3.10/site-packages/py4j/clientserver.py", line 516, in send_command
    raise Py4JNetworkError("Answer from Java side is empty")
py4j.protocol.Py4JNetworkError: Answer from Java side is empty
[2023-01-15T10:17:24.549+0200] {clientserver.py:543} INFO - Closing down clientserver connection
[2023-01-15T10:17:24.550+0200] {java_gateway.py:1055} ERROR - Exception while sending command.
Traceback (most recent call last):
  File "/Library/Frameworks/Python.framework/Versions/3.10/lib/python3.10/site-packages/py4j/clientserver.py", line 516, in send_command
    raise Py4JNetworkError("Answer from Java side is empty")
py4j.protocol.Py4JNetworkError: Answer from Java side is empty

During handling of the above exception, another exception occurred:

Traceback (most recent call last):
  File "/Library/Frameworks/Python.framework/Versions/3.10/lib/python3.10/site-packages/py4j/java_gateway.py", line 1038, in send_command
    response = connection.send_command(command)
  File "/Library/Frameworks/Python.framework/Versions/3.10/lib/python3.10/site-packages/py4j/clientserver.py", line 539, in send_command
    raise Py4JNetworkError(
py4j.protocol.Py4JNetworkError: Error while sending or receiving
[2023-01-15T10:17:24.553+0200] {clientserver.py:543} INFO - Closing down clientserver connection
[2023-01-15T10:17:24.561+0200] {taskinstance.py:1772} ERROR - Task failed with exception
Traceback (most recent call last):
  File "/Library/Frameworks/Python.framework/Versions/3.10/lib/python3.10/site-packages/airflow/decorators/base.py", line 217, in execute
    return_value = super().execute(context)
  File "/Library/Frameworks/Python.framework/Versions/3.10/lib/python3.10/site-packages/airflow/operators/python.py", line 175, in execute
    return_value = self.execute_callable()
  File "/Library/Frameworks/Python.framework/Versions/3.10/lib/python3.10/site-packages/airflow/operators/python.py", line 192, in execute_callable
    return self.python_callable(*self.op_args, **self.op_kwargs)
  File "/Users/nhanchau/gitRepo/Raiway_with_AIrflow/dags/fetching_api.py", line 43, in etl_pipeline
    df_dict = {k: spark.createDataFrame(json.loads(v)) for (k,v) in res_dict.items()}
  File "/Users/nhanchau/gitRepo/Raiway_with_AIrflow/dags/fetching_api.py", line 43, in <dictcomp>
    df_dict = {k: spark.createDataFrame(json.loads(v)) for (k,v) in res_dict.items()}
  File "/Library/Frameworks/Python.framework/Versions/3.10/lib/python3.10/site-packages/pyspark/sql/session.py", line 894, in createDataFrame
    return self._create_dataframe(
  File "/Library/Frameworks/Python.framework/Versions/3.10/lib/python3.10/site-packages/pyspark/sql/session.py", line 939, in _create_dataframe
    jdf = self._jsparkSession.applySchemaToPythonRDD(jrdd.rdd(), struct.json())
  File "/Library/Frameworks/Python.framework/Versions/3.10/lib/python3.10/site-packages/py4j/java_gateway.py", line 1321, in __call__
    return_value = get_return_value(
  File "/Library/Frameworks/Python.framework/Versions/3.10/lib/python3.10/site-packages/pyspark/sql/utils.py", line 190, in deco
    return f(*a, **kw)
  File "/Library/Frameworks/Python.framework/Versions/3.10/lib/python3.10/site-packages/py4j/protocol.py", line 334, in get_return_value
    raise Py4JError(
py4j.protocol.Py4JError: An error occurred while calling o28.applySchemaToPythonRDD
[2023-01-15T10:17:24.655+0200] {taskinstance.py:1322} INFO - Marking task as UP_FOR_RETRY. dag_id=railway_v02, task_id=etl_pipeline, execution_date=20221227T000000, start_date=20230115T081123, end_date=20230115T081724
[2023-01-15T10:17:24.695+0200] {standard_task_runner.py:100} ERROR - Failed to execute job 338 for task etl_pipeline (An error occurred while calling o28.applySchemaToPythonRDD; 13823)
[2023-01-15T11:24:31.101+0200] {taskinstance.py:1087} INFO - Dependencies all met for <TaskInstance: railway_v02.etl_pipeline scheduled__2022-12-27T00:00:00+00:00 [queued]>
[2023-01-15T11:24:31.283+0200] {taskinstance.py:1087} INFO - Dependencies all met for <TaskInstance: railway_v02.etl_pipeline scheduled__2022-12-27T00:00:00+00:00 [queued]>
[2023-01-15T11:24:31.285+0200] {taskinstance.py:1283} INFO - 
--------------------------------------------------------------------------------
[2023-01-15T11:24:31.286+0200] {taskinstance.py:1284} INFO - Starting attempt 3 of 6
[2023-01-15T11:24:31.287+0200] {taskinstance.py:1285} INFO - 
--------------------------------------------------------------------------------
[2023-01-15T11:24:31.421+0200] {taskinstance.py:1304} INFO - Executing <Task(_PythonDecoratedOperator): etl_pipeline> on 2022-12-27 00:00:00+00:00
[2023-01-15T11:24:31.450+0200] {standard_task_runner.py:55} INFO - Started process 14233 to run task
[2023-01-15T11:24:31.507+0200] {standard_task_runner.py:82} INFO - Running: ['airflow', 'tasks', 'run', 'railway_v02', 'etl_pipeline', 'scheduled__2022-12-27T00:00:00+00:00', '--job-id', '464', '--raw', '--subdir', 'DAGS_FOLDER/fetching_api.py', '--cfg-path', '/var/folders/qr/k2__dmk5697g2jyd7w2tpyt80000gn/T/tmppvkjdaaq']
[2023-01-15T11:24:31.513+0200] {standard_task_runner.py:83} INFO - Job 464: Subtask etl_pipeline
[2023-01-15T11:24:32.669+0200] {task_command.py:389} INFO - Running <TaskInstance: railway_v02.etl_pipeline scheduled__2022-12-27T00:00:00+00:00 [running]> on host nhanchaus-macbook-air.local
[2023-01-15T11:24:36.089+0200] {taskinstance.py:1511} INFO - Exporting the following env vars:
AIRFLOW_CTX_DAG_OWNER=Nhan_Chau
AIRFLOW_CTX_DAG_ID=railway_v02
AIRFLOW_CTX_TASK_ID=etl_pipeline
AIRFLOW_CTX_EXECUTION_DATE=2022-12-27T00:00:00+00:00
AIRFLOW_CTX_TRY_NUMBER=3
AIRFLOW_CTX_DAG_RUN_ID=scheduled__2022-12-27T00:00:00+00:00
[2023-01-15T11:25:18.200+0200] {taskinstance.py:1772} ERROR - Task failed with exception
Traceback (most recent call last):
  File "/Library/Frameworks/Python.framework/Versions/3.10/lib/python3.10/site-packages/airflow/decorators/base.py", line 217, in execute
    return_value = super().execute(context)
  File "/Library/Frameworks/Python.framework/Versions/3.10/lib/python3.10/site-packages/airflow/operators/python.py", line 175, in execute
    return_value = self.execute_callable()
  File "/Library/Frameworks/Python.framework/Versions/3.10/lib/python3.10/site-packages/airflow/operators/python.py", line 192, in execute_callable
    return self.python_callable(*self.op_args, **self.op_kwargs)
  File "/Users/nhanchau/gitRepo/Raiway_with_AIrflow/dags/fetching_api.py", line 112, in etl_pipeline
TypeError: SparkSession.stop() missing 1 required positional argument: 'self'
[2023-01-15T11:25:18.218+0200] {taskinstance.py:1322} INFO - Marking task as UP_FOR_RETRY. dag_id=railway_v02, task_id=etl_pipeline, execution_date=20221227T000000, start_date=20230115T092431, end_date=20230115T092518
[2023-01-15T11:25:18.236+0200] {standard_task_runner.py:100} ERROR - Failed to execute job 464 for task etl_pipeline (SparkSession.stop() missing 1 required positional argument: 'self'; 14233)
[2023-01-15T11:25:18.253+0200] {local_task_job.py:159} INFO - Task exited with return code 1
[2023-01-15T11:25:18.283+0200] {taskinstance.py:2582} INFO - 0 downstream tasks scheduled from follow-on schedule check
