[2023-02-04T00:31:11.717+0200] {taskinstance.py:1073} INFO - Dependencies not met for <TaskInstance: railway_v02.etl_pipeline manual__2023-02-03T22:23:30.567165+00:00 [up_for_retry]>, dependency 'Not In Retry Period' FAILED: Task is not ready for retry yet but will be retried automatically. Current date is 2023-02-03T22:31:11.717831+00:00 and task will be retried at 2023-02-03T22:36:08.555031+00:00.
[2023-02-04T00:31:11.721+0200] {local_task_job.py:147} INFO - Task is not able to be run
[2023-02-04T00:31:34.196+0200] {taskinstance.py:1083} INFO - Dependencies all met for <TaskInstance: railway_v02.etl_pipeline manual__2023-02-03T22:23:30.567165+00:00 [queued]>
[2023-02-04T00:31:34.215+0200] {taskinstance.py:1083} INFO - Dependencies all met for <TaskInstance: railway_v02.etl_pipeline manual__2023-02-03T22:23:30.567165+00:00 [queued]>
[2023-02-04T00:31:34.215+0200] {taskinstance.py:1279} INFO - 
--------------------------------------------------------------------------------
[2023-02-04T00:31:34.216+0200] {taskinstance.py:1280} INFO - Starting attempt 4 of 9
[2023-02-04T00:31:34.216+0200] {taskinstance.py:1281} INFO - 
--------------------------------------------------------------------------------
[2023-02-04T00:31:34.227+0200] {taskinstance.py:1300} INFO - Executing <Task(_PythonDecoratedOperator): etl_pipeline> on 2023-02-03 22:23:30.567165+00:00
[2023-02-04T00:31:34.240+0200] {standard_task_runner.py:55} INFO - Started process 38872 to run task
[2023-02-04T00:31:34.250+0200] {standard_task_runner.py:82} INFO - Running: ['airflow', 'tasks', 'run', 'railway_v02', 'etl_pipeline', 'manual__2023-02-03T22:23:30.567165+00:00', '--job-id', '712', '--raw', '--subdir', 'DAGS_FOLDER/fetching_api.py', '--cfg-path', '/var/folders/qr/k2__dmk5697g2jyd7w2tpyt80000gn/T/tmpj25qwx9p']
[2023-02-04T00:31:34.281+0200] {standard_task_runner.py:83} INFO - Job 712: Subtask etl_pipeline
[2023-02-04T00:31:34.345+0200] {task_command.py:388} INFO - Running <TaskInstance: railway_v02.etl_pipeline manual__2023-02-03T22:23:30.567165+00:00 [running]> on host nhanchaus-macbook-air.local
[2023-02-04T00:31:34.396+0200] {taskinstance.py:1507} INFO - Exporting the following env vars:
AIRFLOW_CTX_DAG_OWNER=Nhan_Chau
AIRFLOW_CTX_DAG_ID=railway_v02
AIRFLOW_CTX_TASK_ID=etl_pipeline
AIRFLOW_CTX_EXECUTION_DATE=2023-02-03T22:23:30.567165+00:00
AIRFLOW_CTX_TRY_NUMBER=4
AIRFLOW_CTX_DAG_RUN_ID=manual__2023-02-03T22:23:30.567165+00:00
[2023-02-04T00:31:34.518+0200] {taskinstance.py:1768} ERROR - Task failed with exception
Traceback (most recent call last):
  File "/Library/Frameworks/Python.framework/Versions/3.10/lib/python3.10/site-packages/airflow/decorators/base.py", line 217, in execute
    return_value = super().execute(context)
  File "/Library/Frameworks/Python.framework/Versions/3.10/lib/python3.10/site-packages/airflow/operators/python.py", line 175, in execute
    return_value = self.execute_callable()
  File "/Library/Frameworks/Python.framework/Versions/3.10/lib/python3.10/site-packages/airflow/operators/python.py", line 192, in execute_callable
    return self.python_callable(*self.op_args, **self.op_kwargs)
  File "/Users/nhanchau/gitRepo/Raiway_with_AIrflow/dags/fetching_api.py", line 34, in etl_pipeline
    .getOrCreate())
  File "/Library/Frameworks/Python.framework/Versions/3.10/lib/python3.10/site-packages/pyspark/sql/session.py", line 269, in getOrCreate
    sc = SparkContext.getOrCreate(sparkConf)
  File "/Library/Frameworks/Python.framework/Versions/3.10/lib/python3.10/site-packages/pyspark/context.py", line 483, in getOrCreate
    SparkContext(conf=conf or SparkConf())
  File "/Library/Frameworks/Python.framework/Versions/3.10/lib/python3.10/site-packages/pyspark/context.py", line 195, in __init__
    SparkContext._ensure_initialized(self, gateway=gateway, conf=conf)
  File "/Library/Frameworks/Python.framework/Versions/3.10/lib/python3.10/site-packages/pyspark/context.py", line 417, in _ensure_initialized
    SparkContext._gateway = gateway or launch_gateway(conf)
  File "/Library/Frameworks/Python.framework/Versions/3.10/lib/python3.10/site-packages/pyspark/java_gateway.py", line 106, in launch_gateway
    raise RuntimeError("Java gateway process exited before sending its port number")
RuntimeError: Java gateway process exited before sending its port number
[2023-02-04T00:31:34.534+0200] {taskinstance.py:1318} INFO - Marking task as UP_FOR_RETRY. dag_id=railway_v02, task_id=etl_pipeline, execution_date=20230203T222330, start_date=20230203T223134, end_date=20230203T223134
[2023-02-04T00:31:34.549+0200] {standard_task_runner.py:100} ERROR - Failed to execute job 712 for task etl_pipeline (Java gateway process exited before sending its port number; 38872)
[2023-02-04T00:31:34.587+0200] {local_task_job.py:208} INFO - Task exited with return code 1
[2023-02-04T00:31:34.607+0200] {taskinstance.py:2578} INFO - 0 downstream tasks scheduled from follow-on schedule check
