[2023-02-03T08:36:15.369+0200] {taskinstance.py:1083} INFO - Dependencies all met for <TaskInstance: railway_v02.etl_pipeline manual__2023-02-03T06:36:12.437377+00:00 [queued]>
[2023-02-03T08:36:15.383+0200] {taskinstance.py:1083} INFO - Dependencies all met for <TaskInstance: railway_v02.etl_pipeline manual__2023-02-03T06:36:12.437377+00:00 [queued]>
[2023-02-03T08:36:15.384+0200] {taskinstance.py:1279} INFO - 
--------------------------------------------------------------------------------
[2023-02-03T08:36:15.384+0200] {taskinstance.py:1280} INFO - Starting attempt 1 of 6
[2023-02-03T08:36:15.385+0200] {taskinstance.py:1281} INFO - 
--------------------------------------------------------------------------------
[2023-02-03T08:36:15.397+0200] {taskinstance.py:1300} INFO - Executing <Task(_PythonDecoratedOperator): etl_pipeline> on 2023-02-03 06:36:12.437377+00:00
[2023-02-03T08:36:15.407+0200] {standard_task_runner.py:55} INFO - Started process 71927 to run task
[2023-02-03T08:36:15.413+0200] {standard_task_runner.py:82} INFO - Running: ['airflow', 'tasks', 'run', 'railway_v02', 'etl_pipeline', 'manual__2023-02-03T06:36:12.437377+00:00', '--job-id', '701', '--raw', '--subdir', 'DAGS_FOLDER/fetching_api.py', '--cfg-path', '/var/folders/qr/k2__dmk5697g2jyd7w2tpyt80000gn/T/tmpk3di0atb']
[2023-02-03T08:36:15.416+0200] {standard_task_runner.py:83} INFO - Job 701: Subtask etl_pipeline
[2023-02-03T08:36:15.489+0200] {task_command.py:388} INFO - Running <TaskInstance: railway_v02.etl_pipeline manual__2023-02-03T06:36:12.437377+00:00 [running]> on host nhanchaus-macbook-air.local
[2023-02-03T08:36:15.558+0200] {taskinstance.py:1507} INFO - Exporting the following env vars:
AIRFLOW_CTX_DAG_OWNER=Nhan_Chau
AIRFLOW_CTX_DAG_ID=railway_v02
AIRFLOW_CTX_TASK_ID=etl_pipeline
AIRFLOW_CTX_EXECUTION_DATE=2023-02-03T06:36:12.437377+00:00
AIRFLOW_CTX_TRY_NUMBER=1
AIRFLOW_CTX_DAG_RUN_ID=manual__2023-02-03T06:36:12.437377+00:00
[2023-02-03T08:36:56.164+0200] {local_task_job.py:272} WARNING - State of this instance has been externally set to restarting. Terminating instance.
[2023-02-03T08:36:56.198+0200] {process_utils.py:129} INFO - Sending Signals.SIGTERM to group 71927. PIDs of all processes in the group: [71935, 72022, 72026, 72027, 72028, 72029, 72030, 72031, 72032, 72033, 71927]
[2023-02-03T08:36:56.200+0200] {process_utils.py:84} INFO - Sending the signal Signals.SIGTERM to group 71927
[2023-02-03T08:36:56.203+0200] {taskinstance.py:1479} ERROR - Received SIGTERM. Terminating subprocesses.
[2023-02-03T08:36:56.213+0200] {clientserver.py:538} INFO - Error while receiving.
Traceback (most recent call last):
  File "/Library/Frameworks/Python.framework/Versions/3.10/lib/python3.10/site-packages/py4j/clientserver.py", line 511, in send_command
    answer = smart_decode(self.stream.readline()[:-1])
  File "/Library/Frameworks/Python.framework/Versions/3.10/lib/python3.10/socket.py", line 705, in readinto
    return self._sock.recv_into(b)
  File "/Library/Frameworks/Python.framework/Versions/3.10/lib/python3.10/site-packages/airflow/models/taskinstance.py", line 1481, in signal_handler
    raise AirflowException("Task received SIGTERM signal")
airflow.exceptions.AirflowException: Task received SIGTERM signal
[2023-02-03T08:36:56.221+0200] {clientserver.py:543} INFO - Closing down clientserver connection
[2023-02-03T08:36:56.224+0200] {java_gateway.py:1055} ERROR - Exception while sending command.
Traceback (most recent call last):
  File "/Library/Frameworks/Python.framework/Versions/3.10/lib/python3.10/site-packages/py4j/clientserver.py", line 511, in send_command
    answer = smart_decode(self.stream.readline()[:-1])
  File "/Library/Frameworks/Python.framework/Versions/3.10/lib/python3.10/socket.py", line 705, in readinto
    return self._sock.recv_into(b)
  File "/Library/Frameworks/Python.framework/Versions/3.10/lib/python3.10/site-packages/airflow/models/taskinstance.py", line 1481, in signal_handler
    raise AirflowException("Task received SIGTERM signal")
airflow.exceptions.AirflowException: Task received SIGTERM signal

During handling of the above exception, another exception occurred:

Traceback (most recent call last):
  File "/Library/Frameworks/Python.framework/Versions/3.10/lib/python3.10/site-packages/py4j/java_gateway.py", line 1038, in send_command
    response = connection.send_command(command)
  File "/Library/Frameworks/Python.framework/Versions/3.10/lib/python3.10/site-packages/py4j/clientserver.py", line 539, in send_command
    raise Py4JNetworkError(
py4j.protocol.Py4JNetworkError: Error while sending or receiving
[2023-02-03T08:36:56.228+0200] {clientserver.py:543} INFO - Closing down clientserver connection
[2023-02-03T08:36:56.233+0200] {taskinstance.py:1768} ERROR - Task failed with exception
Traceback (most recent call last):
  File "/Library/Frameworks/Python.framework/Versions/3.10/lib/python3.10/site-packages/airflow/decorators/base.py", line 217, in execute
    return_value = super().execute(context)
  File "/Library/Frameworks/Python.framework/Versions/3.10/lib/python3.10/site-packages/airflow/operators/python.py", line 175, in execute
    return_value = self.execute_callable()
  File "/Library/Frameworks/Python.framework/Versions/3.10/lib/python3.10/site-packages/airflow/operators/python.py", line 192, in execute_callable
    return self.python_callable(*self.op_args, **self.op_kwargs)
  File "/Users/nhanchau/gitRepo/Raiway_with_AIrflow/dags/fetching_api.py", line 101, in etl_pipeline
    (v
  File "/Library/Frameworks/Python.framework/Versions/3.10/lib/python3.10/site-packages/pyspark/sql/readwriter.py", line 1340, in jdbc
    self.mode(mode)._jwrite.jdbc(url, table, jprop)
  File "/Library/Frameworks/Python.framework/Versions/3.10/lib/python3.10/site-packages/py4j/java_gateway.py", line 1321, in __call__
    return_value = get_return_value(
  File "/Library/Frameworks/Python.framework/Versions/3.10/lib/python3.10/site-packages/pyspark/sql/utils.py", line 190, in deco
    return f(*a, **kw)
  File "/Library/Frameworks/Python.framework/Versions/3.10/lib/python3.10/site-packages/py4j/protocol.py", line 334, in get_return_value
    raise Py4JError(
py4j.protocol.Py4JError: An error occurred while calling o216.jdbc
[2023-02-03T08:36:56.290+0200] {taskinstance.py:1318} INFO - Marking task as UP_FOR_RETRY. dag_id=railway_v02, task_id=etl_pipeline, execution_date=20230203T063612, start_date=20230203T063615, end_date=20230203T063656
[2023-02-03T08:36:56.328+0200] {standard_task_runner.py:100} ERROR - Failed to execute job 701 for task etl_pipeline (An error occurred while calling o216.jdbc; 71927)
[2023-02-03T08:36:56.396+0200] {process_utils.py:79} INFO - Process psutil.Process(pid=72033, status='terminated', started='08:36:47') (72033) terminated with exit code None
[2023-02-03T08:36:56.398+0200] {process_utils.py:79} INFO - Process psutil.Process(pid=71927, status='terminated', exitcode=1, started='08:36:15') (71927) terminated with exit code 1
[2023-02-03T08:36:56.399+0200] {process_utils.py:79} INFO - Process psutil.Process(pid=72029, status='terminated', started='08:36:47') (72029) terminated with exit code None
[2023-02-03T08:36:56.402+0200] {process_utils.py:79} INFO - Process psutil.Process(pid=72032, status='terminated', started='08:36:47') (72032) terminated with exit code None
[2023-02-03T08:36:56.404+0200] {process_utils.py:79} INFO - Process psutil.Process(pid=72027, status='terminated', started='08:36:47') (72027) terminated with exit code None
[2023-02-03T08:36:56.503+0200] {process_utils.py:79} INFO - Process psutil.Process(pid=72026, status='terminated', started='08:36:47') (72026) terminated with exit code None
[2023-02-03T08:36:56.505+0200] {process_utils.py:79} INFO - Process psutil.Process(pid=72028, status='terminated', started='08:36:47') (72028) terminated with exit code None
[2023-02-03T08:36:56.508+0200] {process_utils.py:79} INFO - Process psutil.Process(pid=72031, status='terminated', started='08:36:47') (72031) terminated with exit code None
[2023-02-03T08:36:56.510+0200] {process_utils.py:79} INFO - Process psutil.Process(pid=72030, status='terminated', started='08:36:47') (72030) terminated with exit code None
[2023-02-03T08:36:57.019+0200] {process_utils.py:79} INFO - Process psutil.Process(pid=72022, status='terminated', started='08:36:45') (72022) terminated with exit code None
[2023-02-03T08:36:57.239+0200] {process_utils.py:79} INFO - Process psutil.Process(pid=71935, status='terminated', started='08:36:15') (71935) terminated with exit code None
