[2023-01-15T02:52:25.011+0200] {taskinstance.py:1087} INFO - Dependencies all met for <TaskInstance: railway_v01.train_res_df manual__2023-01-14T23:21:57.453068+00:00 [queued]>
[2023-01-15T02:52:25.137+0200] {taskinstance.py:1087} INFO - Dependencies all met for <TaskInstance: railway_v01.train_res_df manual__2023-01-14T23:21:57.453068+00:00 [queued]>
[2023-01-15T02:52:25.139+0200] {taskinstance.py:1283} INFO - 
--------------------------------------------------------------------------------
[2023-01-15T02:52:25.140+0200] {taskinstance.py:1284} INFO - Starting attempt 3 of 6
[2023-01-15T02:52:25.141+0200] {taskinstance.py:1285} INFO - 
--------------------------------------------------------------------------------
[2023-01-15T02:52:25.224+0200] {taskinstance.py:1304} INFO - Executing <Task(_PythonDecoratedOperator): train_res_df> on 2023-01-14 23:21:57.453068+00:00
[2023-01-15T02:52:25.240+0200] {standard_task_runner.py:55} INFO - Started process 53841 to run task
[2023-01-15T02:52:25.256+0200] {standard_task_runner.py:82} INFO - Running: ['airflow', 'tasks', 'run', 'railway_v01', 'train_res_df', 'manual__2023-01-14T23:21:57.453068+00:00', '--job-id', '119', '--raw', '--subdir', 'DAGS_FOLDER/fetching_api.py', '--cfg-path', '/var/folders/qr/k2__dmk5697g2jyd7w2tpyt80000gn/T/tmpii8z_7ge']
[2023-01-15T02:52:25.263+0200] {standard_task_runner.py:83} INFO - Job 119: Subtask train_res_df
[2023-01-15T02:52:25.567+0200] {task_command.py:389} INFO - Running <TaskInstance: railway_v01.train_res_df manual__2023-01-14T23:21:57.453068+00:00 [running]> on host nhanchaus-macbook-air.local
[2023-01-15T02:52:26.031+0200] {taskinstance.py:1511} INFO - Exporting the following env vars:
AIRFLOW_CTX_DAG_OWNER=Nhan_Chau
AIRFLOW_CTX_DAG_ID=railway_v01
AIRFLOW_CTX_TASK_ID=train_res_df
AIRFLOW_CTX_EXECUTION_DATE=2023-01-14T23:21:57.453068+00:00
AIRFLOW_CTX_TRY_NUMBER=3
AIRFLOW_CTX_DAG_RUN_ID=manual__2023-01-14T23:21:57.453068+00:00
[2023-01-15T02:57:28.147+0200] {local_task_job.py:223} WARNING - State of this instance has been externally set to None. Terminating instance.
[2023-01-15T02:57:29.505+0200] {process_utils.py:129} INFO - Sending Signals.SIGTERM to group 53841. PIDs of all processes in the group: [53852, 53841]
[2023-01-15T02:57:29.707+0200] {process_utils.py:84} INFO - Sending the signal Signals.SIGTERM to group 53841
[2023-01-15T02:57:30.166+0200] {taskinstance.py:1483} ERROR - Received SIGTERM. Terminating subprocesses.
[2023-01-15T02:57:31.415+0200] {clientserver.py:538} INFO - Error while receiving.
Traceback (most recent call last):
  File "/Library/Frameworks/Python.framework/Versions/3.10/lib/python3.10/site-packages/py4j/clientserver.py", line 511, in send_command
    answer = smart_decode(self.stream.readline()[:-1])
  File "/Library/Frameworks/Python.framework/Versions/3.10/lib/python3.10/socket.py", line 705, in readinto
    return self._sock.recv_into(b)
  File "/Library/Frameworks/Python.framework/Versions/3.10/lib/python3.10/site-packages/airflow/models/taskinstance.py", line 1485, in signal_handler
    raise AirflowException("Task received SIGTERM signal")
airflow.exceptions.AirflowException: Task received SIGTERM signal
[2023-01-15T02:57:33.083+0200] {clientserver.py:543} INFO - Closing down clientserver connection
[2023-01-15T02:57:33.732+0200] {java_gateway.py:1055} ERROR - Exception while sending command.
Traceback (most recent call last):
  File "/Library/Frameworks/Python.framework/Versions/3.10/lib/python3.10/site-packages/py4j/clientserver.py", line 511, in send_command
    answer = smart_decode(self.stream.readline()[:-1])
  File "/Library/Frameworks/Python.framework/Versions/3.10/lib/python3.10/socket.py", line 705, in readinto
    return self._sock.recv_into(b)
  File "/Library/Frameworks/Python.framework/Versions/3.10/lib/python3.10/site-packages/airflow/models/taskinstance.py", line 1485, in signal_handler
    raise AirflowException("Task received SIGTERM signal")
airflow.exceptions.AirflowException: Task received SIGTERM signal

During handling of the above exception, another exception occurred:

Traceback (most recent call last):
  File "/Library/Frameworks/Python.framework/Versions/3.10/lib/python3.10/site-packages/py4j/java_gateway.py", line 1038, in send_command
    response = connection.send_command(command)
  File "/Library/Frameworks/Python.framework/Versions/3.10/lib/python3.10/site-packages/py4j/clientserver.py", line 539, in send_command
    raise Py4JNetworkError(
py4j.protocol.Py4JNetworkError: Error while sending or receiving
[2023-01-15T02:57:35.476+0200] {clientserver.py:543} INFO - Closing down clientserver connection
[2023-01-15T02:57:36.943+0200] {taskinstance.py:1772} ERROR - Task failed with exception
Traceback (most recent call last):
  File "/Library/Frameworks/Python.framework/Versions/3.10/lib/python3.10/site-packages/airflow/decorators/base.py", line 217, in execute
    return_value = super().execute(context)
  File "/Library/Frameworks/Python.framework/Versions/3.10/lib/python3.10/site-packages/airflow/operators/python.py", line 175, in execute
    return_value = self.execute_callable()
  File "/Library/Frameworks/Python.framework/Versions/3.10/lib/python3.10/site-packages/airflow/operators/python.py", line 192, in execute_callable
    return self.python_callable(*self.op_args, **self.op_kwargs)
  File "/Users/nhanchau/gitRepo/Raiway_with_AIrflow/dags/fetching_api.py", line 47, in respond_to_DF
    df: DataFrame = spark.createDataFrame(json.loads(res))
  File "/Library/Frameworks/Python.framework/Versions/3.10/lib/python3.10/site-packages/pyspark/sql/session.py", line 894, in createDataFrame
    return self._create_dataframe(
  File "/Library/Frameworks/Python.framework/Versions/3.10/lib/python3.10/site-packages/pyspark/sql/session.py", line 936, in _create_dataframe
    rdd, struct = self._createFromLocal(map(prepare, data), schema)
  File "/Library/Frameworks/Python.framework/Versions/3.10/lib/python3.10/site-packages/pyspark/sql/session.py", line 648, in _createFromLocal
    return self._sc.parallelize(internal_data), struct
  File "/Library/Frameworks/Python.framework/Versions/3.10/lib/python3.10/site-packages/pyspark/context.py", line 674, in parallelize
    jrdd = self._serialize_to_jvm(c, serializer, reader_func, createRDDServer)
  File "/Library/Frameworks/Python.framework/Versions/3.10/lib/python3.10/site-packages/pyspark/context.py", line 720, in _serialize_to_jvm
    return reader_func(tempFile.name)
  File "/Library/Frameworks/Python.framework/Versions/3.10/lib/python3.10/site-packages/pyspark/context.py", line 668, in reader_func
    return self._jvm.PythonRDD.readRDDFromFile(self._jsc, temp_filename, numSlices)
  File "/Library/Frameworks/Python.framework/Versions/3.10/lib/python3.10/site-packages/py4j/java_gateway.py", line 1321, in __call__
    return_value = get_return_value(
  File "/Library/Frameworks/Python.framework/Versions/3.10/lib/python3.10/site-packages/pyspark/sql/utils.py", line 190, in deco
    return f(*a, **kw)
  File "/Library/Frameworks/Python.framework/Versions/3.10/lib/python3.10/site-packages/py4j/protocol.py", line 334, in get_return_value
    raise Py4JError(
py4j.protocol.Py4JError: An error occurred while calling z:org.apache.spark.api.python.PythonRDD.readRDDFromFile
[2023-01-15T02:57:53.561+0200] {taskinstance.py:1322} INFO - Marking task as UP_FOR_RETRY. dag_id=railway_v01, task_id=train_res_df, execution_date=20230114T232157, start_date=20230115T005225, end_date=20230115T005750
[2023-01-15T02:58:04.803+0200] {standard_task_runner.py:100} ERROR - Failed to execute job 119 for task train_res_df (An error occurred while calling z:org.apache.spark.api.python.PythonRDD.readRDDFromFile; 53841)
[2023-01-15T02:58:05.977+0200] {process_utils.py:79} INFO - Process psutil.Process(pid=53841, status='terminated', exitcode=1, started='02:52:25') (53841) terminated with exit code 1
[2023-01-15T02:58:29.661+0200] {process_utils.py:79} INFO - Process psutil.Process(pid=53852, status='terminated', started='02:52:26') (53852) terminated with exit code None
