[2023-01-15T10:11:26.887+0200] {taskinstance.py:1087} INFO - Dependencies all met for <TaskInstance: railway_v02.etl_pipeline scheduled__2022-12-18T00:00:00+00:00 [queued]>
[2023-01-15T10:11:27.119+0200] {taskinstance.py:1087} INFO - Dependencies all met for <TaskInstance: railway_v02.etl_pipeline scheduled__2022-12-18T00:00:00+00:00 [queued]>
[2023-01-15T10:11:27.120+0200] {taskinstance.py:1283} INFO - 
--------------------------------------------------------------------------------
[2023-01-15T10:11:27.120+0200] {taskinstance.py:1284} INFO - Starting attempt 3 of 6
[2023-01-15T10:11:27.121+0200] {taskinstance.py:1285} INFO - 
--------------------------------------------------------------------------------
[2023-01-15T10:11:27.162+0200] {taskinstance.py:1304} INFO - Executing <Task(_PythonDecoratedOperator): etl_pipeline> on 2022-12-18 00:00:00+00:00
[2023-01-15T10:11:27.256+0200] {standard_task_runner.py:55} INFO - Started process 14108 to run task
[2023-01-15T10:11:27.329+0200] {standard_task_runner.py:82} INFO - Running: ['airflow', 'tasks', 'run', 'railway_v02', 'etl_pipeline', 'scheduled__2022-12-18T00:00:00+00:00', '--job-id', '348', '--raw', '--subdir', 'DAGS_FOLDER/fetching_api.py', '--cfg-path', '/var/folders/qr/k2__dmk5697g2jyd7w2tpyt80000gn/T/tmpyl_9xwra']
[2023-01-15T10:11:27.339+0200] {standard_task_runner.py:83} INFO - Job 348: Subtask etl_pipeline
[2023-01-15T10:11:28.349+0200] {task_command.py:389} INFO - Running <TaskInstance: railway_v02.etl_pipeline scheduled__2022-12-18T00:00:00+00:00 [running]> on host nhanchaus-macbook-air.local
[2023-01-15T10:11:29.408+0200] {taskinstance.py:1511} INFO - Exporting the following env vars:
AIRFLOW_CTX_DAG_OWNER=Nhan_Chau
AIRFLOW_CTX_DAG_ID=railway_v02
AIRFLOW_CTX_TASK_ID=etl_pipeline
AIRFLOW_CTX_EXECUTION_DATE=2022-12-18T00:00:00+00:00
AIRFLOW_CTX_TRY_NUMBER=3
AIRFLOW_CTX_DAG_RUN_ID=scheduled__2022-12-18T00:00:00+00:00
[2023-01-15T10:16:39.214+0200] {clientserver.py:538} INFO - Error while receiving.
Traceback (most recent call last):
  File "/Library/Frameworks/Python.framework/Versions/3.10/lib/python3.10/site-packages/py4j/clientserver.py", line 516, in send_command
    raise Py4JNetworkError("Answer from Java side is empty")
py4j.protocol.Py4JNetworkError: Answer from Java side is empty
[2023-01-15T10:16:40.474+0200] {clientserver.py:543} INFO - Closing down clientserver connection
[2023-01-15T10:16:40.789+0200] {java_gateway.py:1055} ERROR - Exception while sending command.
Traceback (most recent call last):
  File "/Library/Frameworks/Python.framework/Versions/3.10/lib/python3.10/site-packages/py4j/clientserver.py", line 516, in send_command
    raise Py4JNetworkError("Answer from Java side is empty")
py4j.protocol.Py4JNetworkError: Answer from Java side is empty

During handling of the above exception, another exception occurred:

Traceback (most recent call last):
  File "/Library/Frameworks/Python.framework/Versions/3.10/lib/python3.10/site-packages/py4j/java_gateway.py", line 1038, in send_command
    response = connection.send_command(command)
  File "/Library/Frameworks/Python.framework/Versions/3.10/lib/python3.10/site-packages/py4j/clientserver.py", line 539, in send_command
    raise Py4JNetworkError(
py4j.protocol.Py4JNetworkError: Error while sending or receiving
[2023-01-15T10:16:40.889+0200] {clientserver.py:543} INFO - Closing down clientserver connection
[2023-01-15T10:16:41.061+0200] {taskinstance.py:1772} ERROR - Task failed with exception
Traceback (most recent call last):
  File "/Library/Frameworks/Python.framework/Versions/3.10/lib/python3.10/site-packages/airflow/decorators/base.py", line 217, in execute
    return_value = super().execute(context)
  File "/Library/Frameworks/Python.framework/Versions/3.10/lib/python3.10/site-packages/airflow/operators/python.py", line 175, in execute
    return_value = self.execute_callable()
  File "/Library/Frameworks/Python.framework/Versions/3.10/lib/python3.10/site-packages/airflow/operators/python.py", line 192, in execute_callable
    return self.python_callable(*self.op_args, **self.op_kwargs)
  File "/Users/nhanchau/gitRepo/Raiway_with_AIrflow/dags/fetching_api.py", line 35, in etl_pipeline
    .getOrCreate())
  File "/Library/Frameworks/Python.framework/Versions/3.10/lib/python3.10/site-packages/pyspark/sql/session.py", line 269, in getOrCreate
    sc = SparkContext.getOrCreate(sparkConf)
  File "/Library/Frameworks/Python.framework/Versions/3.10/lib/python3.10/site-packages/pyspark/context.py", line 483, in getOrCreate
    SparkContext(conf=conf or SparkConf())
  File "/Library/Frameworks/Python.framework/Versions/3.10/lib/python3.10/site-packages/pyspark/context.py", line 197, in __init__
    self._do_init(
  File "/Library/Frameworks/Python.framework/Versions/3.10/lib/python3.10/site-packages/pyspark/context.py", line 282, in _do_init
    self._jsc = jsc or self._initialize_context(self._conf._jconf)
  File "/Library/Frameworks/Python.framework/Versions/3.10/lib/python3.10/site-packages/pyspark/context.py", line 402, in _initialize_context
    return self._jvm.JavaSparkContext(jconf)
  File "/Library/Frameworks/Python.framework/Versions/3.10/lib/python3.10/site-packages/py4j/java_gateway.py", line 1585, in __call__
    return_value = get_return_value(
  File "/Library/Frameworks/Python.framework/Versions/3.10/lib/python3.10/site-packages/py4j/protocol.py", line 334, in get_return_value
    raise Py4JError(
py4j.protocol.Py4JError: An error occurred while calling None.org.apache.spark.api.java.JavaSparkContext
[2023-01-15T10:16:41.655+0200] {clientserver.py:538} INFO - Error while receiving.
Traceback (most recent call last):
  File "/Library/Frameworks/Python.framework/Versions/3.10/lib/python3.10/site-packages/py4j/clientserver.py", line 511, in send_command
    answer = smart_decode(self.stream.readline()[:-1])
  File "/Library/Frameworks/Python.framework/Versions/3.10/lib/python3.10/socket.py", line 705, in readinto
    return self._sock.recv_into(b)
ConnectionResetError: [Errno 54] Connection reset by peer
[2023-01-15T10:16:41.924+0200] {clientserver.py:543} INFO - Closing down clientserver connection
[2023-01-15T10:16:41.926+0200] {java_gateway.py:1055} ERROR - Exception while sending command.
Traceback (most recent call last):
  File "/Library/Frameworks/Python.framework/Versions/3.10/lib/python3.10/site-packages/py4j/clientserver.py", line 511, in send_command
    answer = smart_decode(self.stream.readline()[:-1])
  File "/Library/Frameworks/Python.framework/Versions/3.10/lib/python3.10/socket.py", line 705, in readinto
    return self._sock.recv_into(b)
ConnectionResetError: [Errno 54] Connection reset by peer

During handling of the above exception, another exception occurred:

Traceback (most recent call last):
  File "/Library/Frameworks/Python.framework/Versions/3.10/lib/python3.10/site-packages/py4j/java_gateway.py", line 1038, in send_command
    response = connection.send_command(command)
  File "/Library/Frameworks/Python.framework/Versions/3.10/lib/python3.10/site-packages/py4j/clientserver.py", line 539, in send_command
    raise Py4JNetworkError(
py4j.protocol.Py4JNetworkError: Error while sending or receiving
[2023-01-15T10:16:42.001+0200] {clientserver.py:543} INFO - Closing down clientserver connection
[2023-01-15T10:16:42.004+0200] {clientserver.py:543} INFO - Closing down clientserver connection
[2023-01-15T10:16:42.007+0200] {clientserver.py:543} INFO - Closing down clientserver connection
[2023-01-15T10:16:42.012+0200] {clientserver.py:543} INFO - Closing down clientserver connection
[2023-01-15T10:16:42.013+0200] {clientserver.py:543} INFO - Closing down clientserver connection
[2023-01-15T10:16:42.015+0200] {clientserver.py:543} INFO - Closing down clientserver connection
[2023-01-15T10:16:42.015+0200] {clientserver.py:543} INFO - Closing down clientserver connection
[2023-01-15T10:16:42.017+0200] {clientserver.py:543} INFO - Closing down clientserver connection
[2023-01-15T10:16:42.020+0200] {clientserver.py:543} INFO - Closing down clientserver connection
[2023-01-15T10:16:42.024+0200] {clientserver.py:543} INFO - Closing down clientserver connection
[2023-01-15T10:16:42.025+0200] {clientserver.py:543} INFO - Closing down clientserver connection
[2023-01-15T10:16:42.026+0200] {clientserver.py:543} INFO - Closing down clientserver connection
[2023-01-15T10:16:42.028+0200] {clientserver.py:543} INFO - Closing down clientserver connection
[2023-01-15T10:16:42.031+0200] {clientserver.py:543} INFO - Closing down clientserver connection
[2023-01-15T10:16:42.041+0200] {clientserver.py:543} INFO - Closing down clientserver connection
[2023-01-15T10:16:42.050+0200] {clientserver.py:543} INFO - Closing down clientserver connection
[2023-01-15T10:16:42.051+0200] {clientserver.py:543} INFO - Closing down clientserver connection
[2023-01-15T10:16:42.216+0200] {clientserver.py:543} INFO - Closing down clientserver connection
[2023-01-15T10:16:42.225+0200] {clientserver.py:543} INFO - Closing down clientserver connection
[2023-01-15T10:16:42.519+0200] {taskinstance.py:1322} INFO - Marking task as UP_FOR_RETRY. dag_id=railway_v02, task_id=etl_pipeline, execution_date=20221218T000000, start_date=20230115T081126, end_date=20230115T081642
[2023-01-15T10:16:42.886+0200] {standard_task_runner.py:100} ERROR - Failed to execute job 348 for task etl_pipeline (An error occurred while calling None.org.apache.spark.api.java.JavaSparkContext; 14108)
